Workbook

Sheet RESUMEN GENERAL
B1: TESORERÍA 5°B — RESUMEN GENERAL CONSOLIDADO
B2: Dinero efectivamente recibido, utilizado y disponible. El Monto Real en Tesorería no incluye aportes pendientes.
B4: CONCEPTO | C4: TESORERÍA | D4: PRESIDENTA | E4: TOTAL CURSO
B5: INGRESOS EFECTIVAMENTE RECIBIDOS | C5: =SUMIFS(MOVIMIENTOS!$I:$I,MOVIMIENTOS!$D:$D,"Aporte",MOVIMIENTOS!$G:$G,"Tesorería")+SUMIFS(MOVIMIENTOS!$I:$I,MOVIMIENTOS!$D:$D,"Ingreso",MOVIMIENTOS!$G:$G,"Tesorería") -> 404000 | D5: =SUMIFS(MOVIMIENTOS!$I:$I,MOVIMIENTOS!$D:$D,"Aporte",MOVIMIENTOS!$G:$G,"Presidenta")+SUMIFS(MOVIMIENTOS!$I:$I,MOVIMIENTOS!$D:$D,"Ingreso",MOVIMIENTOS!$G:$G,"Presidenta") -> 106000 | E5: =C5+D5 -> 510000
B6: EGRESOS EFECTIVAMENTE PAGADOS | C6: =SUMIFS(MOVIMIENTOS!$I:$I,MOVIMIENTOS!$D:$D,"Egreso",MOVIMIENTOS!$G:$G,"Tesorería") -> 200970 | D6: =SUMIFS(MOVIMIENTOS!$I:$I,MOVIMIENTOS!$D:$D,"Egreso",MOVIMIENTOS!$G:$G,"Presidenta") -> 74692 | E6: =C6+D6 -> 275662
B7: MONTO REAL EN TESORERÍA | C7: =C5-C6 -> 203030 | D7: =D5-D6 -> 31308 | E7: =C7+D7 -> 234338
B8: FONDOS TOTALES | C8: =C7 -> 203030 | D8: =D7 -> 31308 | E8: =C8+D8 -> 234338
B10: CONTROL DE REFERENCIA DEL ARCHIVO ENTREGADO
B11: Monto Real Tesorería | E11: 203030
B12: Saldo en poder de Presidenta | E12: 31308
B13: Fondos totales | E13: 234338
B15: ÚLTIMOS GASTOS
B16: FECHA | C16: DETALLE | D16: FONDO | E16: MONTO
B17: 46240 | C17: POTES HELADOS - PAPEL CELOFAN | D17: Tesorería | E17: 17330
B18: 46233 | C18: TORTA MANJAR CHOCOLATE 32 P | D18: Tesorería | E18: 25490
B19: 46225 | C19: CUCHARAS | D19: Tesorería | E19: 1100
B20: 46209 | C20: DIFERENCIA POTES (VASOS) | D20: Tesorería | E20: 4250
B21: 46192 | C21: TRANSFERENCIA A PRESIDENTA PALTAS | D21: Tesorería | E21: 5000
B22: 46192 | C22: PAN COMPLETO | D22: Tesorería | E22: 10930
B23: 46192 | C23: TOMATE BEBIDAS | D23: Tesorería | E23: 13040
B24: 46191 | C24: VIENESA ADEREZOS | D24: Tesorería | E24: 18550
B27: DATOS DEL TESORERO/A
B28: Nombre
B29: RUT
B30: Teléfono
B31: Correo

Sheet ORGANIZACION
A1: DATOS DE LA ORGANIZACIÓN
A2: Complete una vez. Estos datos se reutilizan en movimientos, comprobantes e informes.
A4: CAMPO | B4: VALOR
A5: Nombre de la organización | B5: CPA 5°B 2026
A6: Tipo de organización | B6: Curso
A7: Establecimiento / institución | B7: Escuela Palestina
A8: Año | B8: 2026
A9: RUT organización
A10: Dirección
A11: Correo
A12: Teléfono | B12: +569
A13: Representante
A14: RUT representante
A15: Tesorero/a
A16: RUT tesorero/a
A17: Teléfono tesorero/a | B17: +569
A18: Correo tesorero/a
A19: Banco de la organización
A20: Tipo de cuenta
A21: Número de cuenta
A22: Titular de la cuenta
A23: RUT titular
A24: Correo transferencias

Sheet GENERAL
A1: TESORERÍA 5°B — PLANILLA GENERAL CONSOLIDADA
A2: Horizontal y lista para imprimir/exportar. Cuotas obligatorias separadas de extraordinarias. Rojo = Presidenta; sin rojo = Tesorería.
A4: N° | B4: RUT | C4: NOMBRE | D4: APODERADO / TUTOR | E4: MARZO | F4: ABRIL | G4: MAYO | H4: JUNIO | I4: JULIO | J4: AGOSTO | K4: SEPTIEMBRE | L4: OCTUBRE | M4: NOVIEMBRE | N4: DICIEMBRE | O4: TOTAL CUOTAS OBLIGATORIAS | P4: CUMPL PROFESOR | Q4: DÍA ALUMNO / NIÑO | R4: CONVIVENCIA JUNIO | S4: COMPLETADA | T4: CUMPLEAÑOS | U4: RIFA | V4: OTRA EXTRAORDINARIA | W4: TOTAL EXTRAORDINARIO | X4: TOTAL ENTREGADO | Y4: OBSERVACIONES
A5: 1 | B5: 25310795-2 | C5: ARAYA PINO RENATA ANTONELA | D5: PATRICIA PINO | E5: =SUMIFS(MOVIMIENTOS!$I:$I,MOVIMIENTOS!$D:$D,"Aporte",MOVIMIENTOS!$E:$E,"Anual",MOVIMIENTOS!$J:$J,$C5,MOVIMIENTOS!$B:$B,">="&DATE(2026,3,1),MOVIMIENTOS!$B:$B,"<"&DATE(2026,4,1)) -> 3000 | F5: =SUMIFS(MOVIMIENTOS!$I:$I,MOVIMIENTOS!$D:$D,"Aporte",MOVIMIENTOS!$E:$E,"Anual",MOVIMIENTOS!$J:$J,$C5,MOVIMIENTOS!$B:$B,">="&DATE(2026,4,1),MOVIMIENTOS!$B:$B,"<"&DATE(2026,5,1)) -> 3000 | G5: =SUMIFS(MOVIMIENTOS!$I:$I,MOVIMIENTOS!$D:$D,"Aporte",MOVIMIENTOS!$E:$E,"Anual",MOVIMIENTOS!$J:$J,$C5,MOVIMIENTOS!$B:$B,">="&DATE(2026,5,1),MOVIMIENTOS!$B:$B,"<"&DATE(2026,6,1)) -> 3000 | H5: =SUMIFS(MOVIMIENTOS!$I:$I,MOVIMIENTOS!$D:$D,"Aporte",MOVIMIENTOS!$E:$E,"Anual",MOVIMIENTOS!$J:$J,$C5,MOVIMIENTOS!$B:$B,">="&DATE(2026,6,1),MOVIMIENTOS!$B:$B,"<"&DATE(2026,7,1)) -> 3000 | I5: =SUMIFS(MOVIMIENTOS!$I:$I,MOVIMIENTOS!$D:$D,"Aporte",MOVIMIENTOS!$E:$E,"Anual",MOVIMIENTOS!$J:$J,$C5,MOVIMIENTOS!$B:$B,">="&DATE(2026,7,1),MOVIMIENTOS!$B:$B,"<"&DATE(2026,8,1)) -> 3000 | J5: =SUMIFS(MOVIMIENTOS!$I:$I,MOVIMIENTOS!$D:$D,"Aporte",MOVIMIENTOS!$E:$E,"Anual",MOVIMIENTOS!$J:$J,$C5,MOVIMIENTOS!$B:$B,">="&DATE(2026,8,1),MOVIMIENTOS!$B:$B,"<"&DATE(2026,9,1)) -> 0 | K5: =SUMIFS(MOVIMIENTOS!$I:$I,MOVIMIENTOS!$D:$D,"Aporte",MOVIMIENTOS!$E:$E,"Anual",MOVIMIENTOS!$J:$J,$C5,MOVIMIENTOS!$B:$B,">="&DATE(2026,9,1),MOVIMIENTOS!$B:$B,"<"&DATE(2026,10,1)) -> 0 | L5: =SUMIFS(MOVIMIENTOS!$I:$I,MOVIMIENTOS!$D:$D,"Aporte",MOVIMIENTOS!$E:$E,"Anual",MOVIMIENTOS!$J:$J,$C5,MOVIMIENTOS!$B:$B,">="&DATE(2026,10,1),MOVIMIENTOS!$B:$B,"<"&DATE(2026,11,1)) -> 0 | M5: =SUMIFS(MOVIMIENTOS!$I:$I,MOVIMIENTOS!$D:$D,"Aporte",MOVIMIENTOS!$E:$E,"Anual",MOVIMIENTOS!$J:$J,$C5,MOVIMIENTOS!$B:$B,">="&DATE(2026,11,1),MOVIMIENTOS!$B:$B,"<"&DATE(2026,12,1)) -> 0 | N5: =SUMIFS(MOVIMIENTOS!$I:$I,MOVIMIENTOS!$D:$D,"Aporte",MOVIMIENTOS!$E:$E,"Anual",MOVIMIENTOS!$J:$J,$C5,MOVIMIENTOS!$B:$B,">="&DATE(2026,12,1),MOVIMIENTOS!$B:$B,"<"&DATE(2026,13,1)) -> 0 | O5: =SUM(E5:N5) -> 15000 | P5: =SUMIFS(MOVIMIENTOS!$I:$I,MOVIMIENTOS!$D:$D,"Aporte",MOVIMIENTOS!$E:$E,"Extraordinaria",MOVIMIENTOS!$F:$F,P$4,MOVIMIENTOS!$J:$J,$C5) -> 1000 | Q5: =SUMIFS(MOVIMIENTOS!$I:$I,MOVIMIENTOS!$D:$D,"Aporte",MOVIMIENTOS!$E:$E,"Extraordinaria",MOVIMIENTOS!$F:$F,Q$4,MOVIMIENTOS!$J:$J,$C5) -> 2000 | R5: =SUMIFS(MOVIMIENTOS!$I:$I,MOVIMIENTOS!$D:$D,"Aporte",MOVIMIENTOS!$E:$E,"Extraordinaria",MOVIMIENTOS!$F:$F,R$4,MOVIMIENTOS!$J:$J,$C5) -> 0 | S5: =SUMIFS(MOVIMIENTOS!$I:$I,MOVIMIENTOS!$D:$D,"Aporte",MOVIMIENTOS!$E:$E,"Extraordinaria",MOVIMIENTOS!$F:$F,S$4,MOVIMIENTOS!$J:$J,$C5) -> 0 | T5: =SUMIFS(MOVIMIENTOS!$I:$I,MOVIMIENTOS!$D:$D,"Aporte",MOVIMIENTOS!$E:$E,"Extraordinaria",MOVIMIENTOS!$F:$F,T$4,MOVIMIENTOS!$J:$J,$C5) -> 0 | U5: =SUMIFS(MOVIMIENTOS!$I:$I,MOVIMIENTOS!$D:$D,"Aporte",MOVIMIENTOS!$E:$E,"Extraordinaria",MOVIMIENTOS!$F:$F,U$4,MOVIMIENTOS!$J:$J,$C5) -> 0 | V5: =SUMIFS(MOVIMIENTOS!$I:$I,MOVIMIENTOS!$D:$D,"Aporte",MOVIMIENTOS!$E:$E,"Extraordinaria",MOVIMIENTOS!$F:$F,V$4,MOVIMIENTOS!$J:$J,$C5) -> 0 | W5: =SUM(P5:V5) -> 3000 | X5: =O5+W5 -> 18000
A6: 2 | B6: 25299343-6 | C6: ASTUDILLO PINO TABATA JESÚS | D6: ROXANA PINO | E6: =SUMIFS(MOVIMIENTOS!$I:$I,MOVIMIENTOS!$D:$D,"Aporte",MOVIMIENTOS!$E:$E,"Anual",MOVIMIENTOS!$J:$J,$C6,MOVIMIENTOS!$B:$B,">="&DATE(2026,3,1),MOVIMIENTOS!$B:$B,"<"&DATE(2026,4,1)) -> 3000 | F6: =SUMIFS(MOVIMIENTOS!$I:$I,MOVIMIENTOS!$D:$D,"Aporte",MOVIMIENTOS!$E:$E,"Anual",MOVIMIENTOS!$J:$J,$C6,MOVIMIENTOS!$B:$B,">="&DATE(2026,4,1),MOVIMIENTOS!$B:$B,"<"&DATE(2026,5,1)) -> 0 | G6: =SUMIFS(MOVIMIENTOS!$I:$I,MOVIMIENTOS!$D:$D,"Aporte",MOVIMIENTOS!$E:$E,"Anual",MOVIMIENTOS!$J:$J,$C6,MOVIMIENTOS!$B:$B,">="&DATE(2026,5,1),MOVIMIENTOS!$B:$B,"<"&DATE(2026,6,1)) -> 0 | H6: =SUMIFS(MOVIMIENTOS!$I:$I,MOVIMIENTOS!$D:$D,"Aporte",MOVIMIENTOS!$E:$E,"Anual",MOVIMIENTOS!$J:$J,$C6,MOVIMIENTOS!$B:$B,">="&DATE(2026,6,1),MOVIMIENTOS!$B:$B,"<"&DATE(2026,7,1)) -> 0 | I6: =SUMIFS(MOVIMIENTOS!$I:$I,MOVIMIENTOS!$D:$D,"Aporte",MOVIMIENTOS!$E:$E,"Anual",MOVIMIENTOS!$J:$J,$C6,MOVIMIENTOS!$B:$B,">="&DATE(2026,7,1),MOVIMIENTOS!$B:$B,"<"&DATE(2026,8,1)) -> 0 | J6: =SUMIFS(MOVIMIENTOS!$I:$I,MOVIMIENTOS!$D:$D,"Aporte",MOVIMIENTOS!$E:$E,"Anual",MOVIMIENTOS!$J:$J,$C6,MOVIMIENTOS!$B:$B,">="&DATE(2026,8,1),MOVIMIENTOS!$B:$B,"<"&DATE(2026,9,1)) -> 0 | K6: =SUMIFS(MOVIMIENTOS!$I:$I,MOVIMIENTOS!$D:$D,"Aporte",MOVIMIENTOS!$E:$E,"Anual",MOVIMIENTOS!$J:$J,$C6,MOVIMIENTOS!$B:$B,">="&DATE(2026,9,1),MOVIMIENTOS!$B:$B,"<"&DATE(2026,10,1)) -> 0 | L6: =SUMIFS(MOVIMIENTOS!$I:$I,MOVIMIENTOS!$D:$D,"Aporte",MOVIMIENTOS!$E:$E,"Anual",MOVIMIENTOS!$J:$J,$C6,MOVIMIENTOS!$B:$B,">="&DATE(2026,10,1),MOVIMIENTOS!$B:$B,"<"&DATE(2026,11,1)) -> 0 | M6: =SUMIFS(MOVIMIENTOS!$I:$I,MOVIMIENTOS!$D:$D,"Aporte",MOVIMIENTOS!$E:$E,"Anual",MOVIMIENTOS!$J:$J,$C6,MOVIMIENTOS!$B:$B,">="&DATE(2026,11,1),MOVIMIENTOS!$B:$B,"<"&DATE(2026,12,1)) -> 0 | N6: =SUMIFS(MOVIMIENTOS!$I:$I,MOVIMIENTOS!$D:$D,"Aporte",MOVIMIENTOS!$E:$E,"Anual",MOVIMIENTOS!$J:$J,$C6,MOVIMIENTOS!$B:$B,">="&DATE(2026,12,1),MOVIMIENTOS!$B:$B,"<"&DATE(2026,13,1)) -> 0 | O6: =SUM(E6:N6) -> 3000 | P6: =SUMIFS(MOVIMIENTOS!$I:$I,MOVIMIENTOS!$D:$D,"Aporte",MOVIMIENTOS!$E:$E,"Extraordinaria",MOVIMIENTOS!$F:$F,P$4,MOVIMIENTOS!$J:$J,$C6) -> 1000 | Q6: =SUMIFS(MOVIMIENTOS!$I:$I,MOVIMIENTOS!$D:$D,"Aporte",MOVIMIENTOS!$E:$E,"Extraordinaria",MOVIMIENTOS!$F:$F,Q$4,MOVIMIENTOS!$J:$J,$C6) -> 0 | R6: =SUMIFS(MOVIMIENTOS!$I:$I,MOVIMIENTOS!$D:$D,"Aporte",MOVIMIENTOS!$E:$E,"Extraordinaria",MOVIMIENTOS!$F:$F,R$4,MOVIMIENTOS!$J:$J,$C6) -> 2000 | S6: =SUMIFS(MOVIMIENTOS!$I:$I,MOVIMIENTOS!$D:$D,"Aporte",MOVIMIENTOS!$E:$E,"Extraordinaria",MOVIMIENTOS!$F:$F,S$4,MOVIMIENTOS!$J:$J,$C6) -> 0 | T6: =SUMIFS(MOVIMIENTOS!$I:$I,MOVIMIENTOS!$D:$D,"Aporte",MOVIMIENTOS!$E:$E,"Extraordinaria",MOVIMIENTOS!$F:$F,T$4,MOVIMIENTOS!$J:$J,$C6) -> 0 | U6: =SUMIFS(MOVIMIENTOS!$I:$I,MOVIMIENTOS!$D:$D,"Aporte",MOVIMIENTOS!$E:$E,"Extraordinaria",MOVIMIENTOS!$F:$F,U$4,MOVIMIENTOS!$J:$J,$C6) -> 0 | V6: =SUMIFS(MOVIMIENTOS!$I:$I,MOVIMIENTOS!$D:$D,"Aporte",MOVIMIENTOS!$E:$E,"Extraordinaria",MOVIMIENTOS!$F:$F,V$4,MOVIMIENTOS!$J:$J,$C6) -> 0 | W6: =SUM(P6:V6) -> 3000 | X6: =O6+W6 -> 6000
A7: 3 | B7: 25172569-1 | C7: AZAGRA ABRIGO AMARO ALONSO | D7: BEATRIZ ABRIGO | E7: =SUMIFS(MOVIMIENTOS!$I:$I,MOVIMIENTOS!$D:$D,"Aporte",MOVIMIENTOS!$E:$E,"Anual",MOVIMIENTOS!$J:$J,$C7,MOVIMIENTOS!$B:$B,">="&DATE(2026,3,1),MOVIMIENTOS!$B:$B,"<"&DATE(2026,4,1)) -> 0 | F7: =SUMIFS(MOVIMIENTOS!$I:$I,MOVIMIENTOS!$D:$D,"Aporte",MOVIMIENTOS!$E:$E,"Anual",MOVIMIENTOS!$J:$J,$C7,MOVIMIENTOS!$B:$B,">="&DATE(2026,4,1),MOVIMIENTOS!$B:$B,"<"&DATE(2026,5,1)) -> 0 | G7: =SUMIFS(MOVIMIENTOS!$I:$I,MOVIMIENTOS!$D:$D,"Aporte",MOVIMIENTOS!$E:$E,"Anual",MOVIMIENTOS!$J:$J,$C7,MOVIMIENTOS!$B:$B,">="&DATE(2026,5,1),MOVIMIENTOS!$B:$B,"<"&DATE(2026,6,1)) -> 0 | H7: =SUMIFS(MOVIMIENTOS!$I:$I,MOVIMIENTOS!$D:$D,"Aporte",MOVIMIENTOS!$E:$E,"Anual",MOVIMIENTOS!$J:$J,$C7,MOVIMIENTOS!$B:$B,">="&DATE(2026,6,1),MOVIMIENTOS!$B:$B,"<"&DATE(2026,7,1)) -> 0 | I7: =SUMIFS(MOVIMIENTOS!$I:$I,MOVIMIENTOS!$D:$D,"Aporte",MOVIMIENTOS!$E:$E,"Anual",MOVIMIENTOS!$J:$J,$C7,MOVIMIENTOS!$B:$B,">="&DATE(2026,7,1),MOVIMIENTOS!$B:$B,"<"&DATE(2026,8,1)) -> 0 | J7: =SUMIFS(MOVIMIENTOS!$I:$I,MOVIMIENTOS!$D:$D,"Aporte",MOVIMIENTOS!$E:$E,"Anual",MOVIMIENTOS!$J:$J,$C7,MOVIMIENTOS!$B:$B,">="&DATE(2026,8,1),MOVIMIENTOS!$B:$B,"<"&DATE(2026,9,1)) -> 0 | K7: =SUMIFS(MOVIMIENTOS!$I:$I,MOVIMIENTOS!$D:$D,"Aporte",MOVIMIENTOS!$E:$E,"Anual",MOVIMIENTOS!$J:$J,$C7,MOVIMIENTOS!$B:$B,">="&DATE(2026,9,1),MOVIMIENTOS!$B:$B,"<"&DATE(2026,10,1)) -> 0 | L7: =SUMIFS(MOVIMIENTOS!$I:$I,MOVIMIENTOS!$D:$D,"Aporte",MOVIMIENTOS!$E:$E,"Anual",MOVIMIENTOS!$J:$J,$C7,MOVIMIENTOS!$B:$B,">="&DATE(2026,10,1),MOVIMIENTOS!$B:$B,"<"&DATE(2026,11,1)) -> 0 | M7: =SUMIFS(MOVIMIENTOS!$I:$I,MOVIMIENTOS!$D:$D,"Aporte",MOVIMIENTOS!$E:$E,"Anual",MOVIMIENTOS!$J:$J,$C7,MOVIMIENTOS!$B:$B,">="&DATE(2026,11,1),MOVIMIENTOS!$B:$B,"<"&DATE(2026,12,1)) -> 0 | N7: =SUMIFS(MOVIMIENTOS!$I:$I,MOVIMIENTOS!$D:$D,"Aporte",MOVIMIENTOS!$E:$E,"Anual",MOVIMIENTOS!$J:$J,$C7,MOVIMIENTOS!$B:$B,">="&DATE(2026,12,1),MOVIMIENTOS!$B:$B,"<"&DATE(2026,13,1)) -> 0 | O7: =SUM(E7:N7) -> 0 | P7: =SUMIFS(MOVIMIENTOS!$I:$I,MOVIMIENTOS!$D:$D,"Aporte",MOVIMIENTOS!$E:$E,"Extraordinaria",MOVIMIENTOS!$F:$F,P$4,MOVIMIENTOS!$J:$J,$C7) -> 1000 | Q7: =SUMIFS(MOVIMIENTOS!$I:$I,MOVIMIENTOS!$D:$D,"Aporte",MOVIMIENTOS!$E:$E,"Extraordinaria",MOVIMIENTOS!$F:$F,Q$4,MOVIMIENTOS!$J:$J,$C7) -> 2000 | R7: =SUMIFS(MOVIMIENTOS!$I:$I,MOVIMIENTOS!$D:$D,"Aporte",MOVIMIENTOS!$E:$E,"Extraordinaria",MOVIMIENTOS!$F:$F,R$4,MOVIMIENTOS!$J:$J,$C7) -> 2000 | S7: =SUMIFS(MOVIMIENTOS!$I:$I,MOVIMIENTOS!$D:$D,"Aporte",MOVIMIENTOS!$E:$E,"Extraordinaria",MOVIMIENTOS!$F:$F,S$4,MOVIMIENTOS!$J:$J,$C7) -> 0 | T7: =SUMIFS(MOVIMIENTOS!$I:$I,MOVIMIENTOS!$D:$D,"Aporte",MOVIMIENTOS!$E:$E,"Extraordinaria",MOVIMIENTOS!$F:$F,T$4,MOVIMIENTOS!$J:$J,$C7) -> 0 | U7: =SUMIFS(MOVIMIENTOS!$I:$I,MOVIMIENTOS!$D:$D,"Aporte",MOVIMIENTOS!$E:$E,"Extraordinaria",MOVIMIENTOS!$F:$F,U$4,MOVIMIENTOS!$J:$J,$C7) -> 1000 | V7: =SUMIFS(MOVIMIENTOS!$I:$I,MOVIMIENTOS!$D:$D,"Aporte",MOVIMIENTOS!$E:$E,"Extraordinaria",MOVIMIENTOS!$F:$F,V$4,MOVIMIENTOS!$J:$J,$C7) -> 0 | W7: =SUM(P7:V7) -> 6000 | X7: =O7+W7 -> 6000
A8: 4 | B8: 25074761-6 | C8: BECERRA CARRASCO AGUSTIN SALVADOR THOMAS | D8: ALICIA ARAYA | E8: =SUMIFS(MOVIMIENTOS!$I:$I,MOVIMIENTOS!$D:$D,"Aporte",MOVIMIENTOS!$E:$E,"Anual",MOVIMIENTOS!$J:$J,$C8,MOVIMIENTOS!$B:$B,">="&DATE(2026,3,1),MOVIMIENTOS!$B:$B,"<"&DATE(2026,4,1)) -> 3000 | F8: =SUMIFS(MOVIMIENTOS!$I:$I,MOVIMIENTOS!$D:$D,"Aporte",MOVIMIENTOS!$E:$E,"Anual",MOVIMIENTOS!$J:$J,$C8,MOVIMIENTOS!$B:$B,">="&DATE(2026,4,1),MOVIMIENTOS!$B:$B,"<"&DATE(2026,5,1)) -> 3000 | G8: =SUMIFS(MOVIMIENTOS!$I:$I,MOVIMIENTOS!$D:$D,"Aporte",MOVIMIENTOS!$E:$E,"Anual",MOVIMIENTOS!$J:$J,$C8,MOVIMIENTOS!$B:$B,">="&DATE(2026,5,1),MOVIMIENTOS!$B:$B,"<"&DATE(2026,6,1)) -> 3000 | H8: =SUMIFS(MOVIMIENTOS!$I:$I,MOVIMIENTOS!$D:$D,"Aporte",MOVIMIENTOS!$E:$E,"Anual",MOVIMIENTOS!$J:$J,$C8,MOVIMIENTOS!$B:$B,">="&DATE(2026,6,1),MOVIMIENTOS!$B:$B,"<"&DATE(2026,7,1)) -> 0 | I8: =SUMIFS(MOVIMIENTOS!$I:$I,MOVIMIENTOS!$D:$D,"Aporte",MOVIMIENTOS!$E:$E,"Anual",MOVIMIENTOS!$J:$J,$C8,MOVIMIENTOS!$B:$B,">="&DATE(2026,7,1),MOVIMIENTOS!$B:$B,"<"&DATE(2026,8,1)) -> 0 | J8: =SUMIFS(MOVIMIENTOS!$I:$I,MOVIMIENTOS!$D:$D,"Aporte",MOVIMIENTOS!$E:$E,"Anual",MOVIMIENTOS!$J:$J,$C8,MOVIMIENTOS!$B:$B,">="&DATE(2026,8,1),MOVIMIENTOS!$B:$B,"<"&DATE(2026,9,1)) -> 0 | K8: =SUMIFS(MOVIMIENTOS!$I:$I,MOVIMIENTOS!$D:$D,"Aporte",MOVIMIENTOS!$E:$E,"Anual",MOVIMIENTOS!$J:$J,$C8,MOVIMIENTOS!$B:$B,">="&DATE(2026,9,1),MOVIMIENTOS!$B:$B,"<"&DATE(2026,10,1)) -> 0 | L8: =SUMIFS(MOVIMIENTOS!$I:$I,MOVIMIENTOS!$D:$D,"Aporte",MOVIMIENTOS!$E:$E,"Anual",MOVIMIENTOS!$J:$J,$C8,MOVIMIENTOS!$B:$B,">="&DATE(2026,10,1),MOVIMIENTOS!$B:$B,"<"&DATE(2026,11,1)) -> 0 | M8: =SUMIFS(MOVIMIENTOS!$I:$I,MOVIMIENTOS!$D:$D,"Aporte",MOVIMIENTOS!$E:$E,"Anual",MOVIMIENTOS!$J:$J,$C8,MOVIMIENTOS!$B:$B,">="&DATE(2026,11,1),MOVIMIENTOS!$B:$B,"<"&DATE(2026,12,1)) -> 0 | N8: =SUMIFS(MOVIMIENTOS!$I:$I,MOVIMIENTOS!$D:$D,"Aporte",MOVIMIENTOS!$E:$E,"Anual",MOVIMIENTOS!$J:$J,$C8,MOVIMIENTOS!$B:$B,">="&DATE(2026,12,1),MOVIMIENTOS!$B:$B,"<"&DATE(2026,13,1)) -> 0 | O8: =SUM(E8:N8) -> 9000 | P8: =SUMIFS(MOVIMIENTOS!$I:$I,MOVIMIENTOS!$D:$D,"Aporte",MOVIMIENTOS!$E:$E,"Extraordinaria",MOVIMIENTOS!$F:$F,P$4,MOVIMIENTOS!$J:$J,$C8) -> 1000 | Q8: =SUMIFS(MOVIMIENTOS!$I:$I,MOVIMIENTOS!$D:$D,"Aporte",MOVIMIENTOS!$E:$E,"Extraordinaria",MOVIMIENTOS!$F:$F,Q$4,MOVIMIENTOS!$J:$J,$C8) -> 2000 | R8: =SUMIFS(MOVIMIENTOS!$I:$I,MOVIMIENTOS!$D:$D,"Aporte",MOVIMIENTOS!$E:$E,"Extraordinaria",MOVIMIENTOS!$F:$F,R$4,MOVIMIENTOS!$J:$J,$C8) -> 2000 | S8: =SUMIFS(MOVIMIENTOS!$I:$I,MOVIMIENTOS!$D:$D,"Aporte",MOVIMIENTOS!$E:$E,"Extraordinaria",MOVIMIENTOS!$F:$F,S$4,MOVIMIENTOS!$J:$J,$C8) -> 0 | T8: =SUMIFS(MOVIMIENTOS!$I:$I,MOVIMIENTOS!$D:$D,"Aporte",MOVIMIENTOS!$E:$E,"Extraordinaria",MOVIMIENTOS!$F:$F,T$4,MOVIMIENTOS!$J:$J,$C8) -> 0 | U8: =SUMIFS(MOVIMIENTOS!$I:$I,MOVIMIENTOS!$D:$D,"Aporte",MOVIMIENTOS!$E:$E,"Extraordinaria",MOVIMIENTOS!$F:$F,U$4,MOVIMIENTOS!$J:$J,$C8) -> 0 | V8: =SUMIFS(MOVIMIENTOS!$I:$I,MOVIMIENTOS!$D:$D,"Aporte",MOVIMIENTOS!$E:$E,"Extraordinaria",MOVIMIENTOS!$F:$F,V$4,MOVIMIENTOS!$J:$J,$C8) -> 0 | W8: =SUM(P8:V8) -> 5000 | X8: =O8+W8 -> 14000
C9: BERTEL MONTES GLEYMIS | E9: =SUMIFS(MOVIMIENTOS!$I:$I,MOVIMIENTOS!$D:$D,"Aporte",MOVIMIENTOS!$E:$E,"Anual",MOVIMIENTOS!$J:$J,$C9,MOVIMIENTOS!$B:$B,">="&DATE(2026,3,1),MOVIMIENTOS!$B:$B,"<"&DATE(2026,4,1)) -> 3000 | F9: =SUMIFS(MOVIMIENTOS!$I:$I,MOVIMIENTOS!$D:$D,"Aporte",MOVIMIENTOS!$E:$E,"Anual",MOVIMIENTOS!$J:$J,$C9,MOVIMIENTOS!$B:$B,">="&DATE(2026,4,1),MOVIMIENTOS!$B:$B,"<"&DATE(2026,5,1)) -> 0 | G9: =SUMIFS(MOVIMIENTOS!$I:$I,MOVIMIENTOS!$D:$D,"Aporte",MOVIMIENTOS!$E:$E,"Anual",MOVIMIENTOS!$J:$J,$C9,MOVIMIENTOS!$B:$B,">="&DATE(2026,5,1),MOVIMIENTOS!$B:$B,"<"&DATE(2026,6,1)) -> 0 | H9: =SUMIFS(MOVIMIENTOS!$I:$I,MOVIMIENTOS!$D:$D,"Aporte",MOVIMIENTOS!$E:$E,"Anual",MOVIMIENTOS!$J:$J,$C9,MOVIMIENTOS!$B:$B,">="&DATE(2026,6,1),MOVIMIENTOS!$B:$B,"<"&DATE(2026,7,1)) -> 0 | I9: =SUMIFS(MOVIMIENTOS!$I:$I,MOVIMIENTOS!$D:$D,"Aporte",MOVIMIENTOS!$E:$E,"Anual",MOVIMIENTOS!$J:$J,$C9,MOVIMIENTOS!$B:$B,">="&DATE(2026,7,1),MOVIMIENTOS!$B:$B,"<"&DATE(2026,8,1)) -> 0 | J9: =SUMIFS(MOVIMIENTOS!$I:$I,MOVIMIENTOS!$D:$D,"Aporte",MOVIMIENTOS!$E:$E,"Anual",MOVIMIENTOS!$J:$J,$C9,MOVIMIENTOS!$B:$B,">="&DATE(2026,8,1),MOVIMIENTOS!$B:$B,"<"&DATE(2026,9,1)) -> 0 | K9: =SUMIFS(MOVIMIENTOS!$I:$I,MOVIMIENTOS!$D:$D,"Aporte",MOVIMIENTOS!$E:$E,"Anual",MOVIMIENTOS!$J:$J,$C9,MOVIMIENTOS!$B:$B,">="&DATE(2026,9,1),MOVIMIENTOS!$B:$B,"<"&DATE(2026,10,1)) -> 0 | L9: =SUMIFS(MOVIMIENTOS!$I:$I,MOVIMIENTOS!$D:$D,"Aporte",MOVIMIENTOS!$E:$E,"Anual",MOVIMIENTOS!$J:$J,$C9,MOVIMIENTOS!$B:$B,">="&DATE(2026,10,1),MOVIMIENTOS!$B:$B,"<"&DATE(2026,11,1)) -> 0 | M9: =SUMIFS(MOVIMIENTOS!$I:$I,MOVIMIENTOS!$D:$D,"Aporte",MOVIMIENTOS!$E:$E,"Anual",MOVIMIENTOS!$J:$J,$C9,MOVIMIENTOS!$B:$B,">="&DATE(2026,11,1),MOVIMIENTOS!$B:$B,"<"&DATE(2026,12,1)) -> 0 | N9: =SUMIFS(MOVIMIENTOS!$I:$I,MOVIMIENTOS!$D:$D,"Aporte",MOVIMIENTOS!$E:$E,"Anual",MOVIMIENTOS!$J:$J,$C9,MOVIMIENTOS!$B:$B,">="&DATE(2026,12,1),MOVIMIENTOS!$B:$B,"<"&DATE(2026,13,1)) -> 0 | O9: =SUM(E9:N9) -> 3000 | P9: =SUMIFS(MOVIMIENTOS!$I:$I,MOVIMIENTOS!$D:$D,"Aporte",MOVIMIENTOS!$E:$E,"Extraordinaria",MOVIMIENTOS!$F:$F,P$4,MOVIMIENTOS!$J:$J,$C9) -> 0 | Q9: =SUMIFS(MOVIMIENTOS!$I:$I,MOVIMIENTOS!$D:$D,"Aporte",MOVIMIENTOS!$E:$E,"Extraordinaria",MOVIMIENTOS!$F:$F,Q$4,MOVIMIENTOS!$J:$J,$C9) -> 0 | R9: =SUMIFS(MOVIMIENTOS!$I:$I,MOVIMIENTOS!$D:$D,"Aporte",MOVIMIENTOS!$E:$E,"Extraordinaria",MOVIMIENTOS!$F:$F,R$4,MOVIMIENTOS!$J:$J,$C9) -> 0 | S9: =SUMIFS(MOVIMIENTOS!$I:$I,MOVIMIENTOS!$D:$D,"Aporte",MOVIMIENTOS!$E:$E,"Extraordinaria",MOVIMIENTOS!$F:$F,S$4,MOVIMIENTOS!$J:$J,$C9) -> 0 | T9: =SUMIFS(MOVIMIENTOS!$I:$I,MOVIMIENTOS!$D:$D,"Aporte",MOVIMIENTOS!$E:$E,"Extraordinaria",MOVIMIENTOS!$F:$F,T$4,MOVIMIENTOS!$J:$J,$C9) -> 0 | U9: =SUMIFS(MOVIMIENTOS!$I:$I,MOVIMIENTOS!$D:$D,"Aporte",MOVIMIENTOS!$E:$E,"Extraordinaria",MOVIMIENTOS!$F:$F,U$4,MOVIMIENTOS!$J:$J,$C9) -> 0 | V9: =SUMIFS(MOVIMIENTOS!$I:$I,MOVIMIENTOS!$D:$D,"Aporte",MOVIMIENTOS!$E:$E,"Extraordinaria",MOVIMIENTOS!$F:$F,V$4,MOVIMIENTOS!$J:$J,$C9) -> 0 | W9: =SUM(P9:V9) -> 0 | X9: =O9+W9 -> 3000
A10: 6 | B10: 25186502-7 | C10: CASTILLO DÍAZ NAHUEL ANDRÉS | E10: =SUMIFS(MOVIMIENTOS!$I:$I,MOVIMIENTOS!$D:$D,"Aporte",MOVIMIENTOS!$E:$E,"Anual",MOVIMIENTOS!$J:$J,$C10,MOVIMIENTOS!$B:$B,">="&DATE(2026,3,1),MOVIMIENTOS!$B:$B,"<"&DATE(2026,4,1)) -> 0 | F10: =SUMIFS(MOVIMIENTOS!$I:$I,MOVIMIENTOS!$D:$D,"Aporte",MOVIMIENTOS!$E:$E,"Anual",MOVIMIENTOS!$J:$J,$C10,MOVIMIENTOS!$B:$B,">="&DATE(2026,4,1),MOVIMIENTOS!$B:$B,"<"&DATE(2026,5,1)) -> 0 | G10: =SUMIFS(MOVIMIENTOS!$I:$I,MOVIMIENTOS!$D:$D,"Aporte",MOVIMIENTOS!$E:$E,"Anual",MOVIMIENTOS!$J:$J,$C10,MOVIMIENTOS!$B:$B,">="&DATE(2026,5,1),MOVIMIENTOS!$B:$B,"<"&DATE(2026,6,1)) -> 0 | H10: =SUMIFS(MOVIMIENTOS!$I:$I,MOVIMIENTOS!$D:$D,"Aporte",MOVIMIENTOS!$E:$E,"Anual",MOVIMIENTOS!$J:$J,$C10,MOVIMIENTOS!$B:$B,">="&DATE(2026,6,1),MOVIMIENTOS!$B:$B,"<"&DATE(2026,7,1)) -> 0 | I10: =SUMIFS(MOVIMIENTOS!$I:$I,MOVIMIENTOS!$D:$D,"Aporte",MOVIMIENTOS!$E:$E,"Anual",MOVIMIENTOS!$J:$J,$C10,MOVIMIENTOS!$B:$B,">="&DATE(2026,7,1),MOVIMIENTOS!$B:$B,"<"&DATE(2026,8,1)) -> 0 | J10: =SUMIFS(MOVIMIENTOS!$I:$I,MOVIMIENTOS!$D:$D,"Aporte",MOVIMIENTOS!$E:$E,"Anual",MOVIMIENTOS!$J:$J,$C10,MOVIMIENTOS!$B:$B,">="&DATE(2026,8,1),MOVIMIENTOS!$B:$B,"<"&DATE(2026,9,1)) -> 0 | K10: =SUMIFS(MOVIMIENTOS!$I:$I,MOVIMIENTOS!$D:$D,"Aporte",MOVIMIENTOS!$E:$E,"Anual",MOVIMIENTOS!$J:$J,$C10,MOVIMIENTOS!$B:$B,">="&DATE(2026,9,1),MOVIMIENTOS!$B:$B,"<"&DATE(2026,10,1)) -> 0 | L10: =SUMIFS(MOVIMIENTOS!$I:$I,MOVIMIENTOS!$D:$D,"Aporte",MOVIMIENTOS!$E:$E,"Anual",MOVIMIENTOS!$J:$J,$C10,MOVIMIENTOS!$B:$B,">="&DATE(2026,10,1),MOVIMIENTOS!$B:$B,"<"&DATE(2026,11,1)) -> 0 | M10: =SUMIFS(MOVIMIENTOS!$I:$I,MOVIMIENTOS!$D:$D,"Aporte",MOVIMIENTOS!$E:$E,"Anual",MOVIMIENTOS!$J:$J,$C10,MOVIMIENTOS!$B:$B,">="&DATE(2026,11,1),MOVIMIENTOS!$B:$B,"<"&DATE(2026,12,1)) -> 0 | N10: =SUMIFS(MOVIMIENTOS!$I:$I,MOVIMIENTOS!$D:$D,"Aporte",MOVIMIENTOS!$E:$E,"Anual",MOVIMIENTOS!$J:$J,$C10,MOVIMIENTOS!$B:$B,">="&DATE(2026,12,1),MOVIMIENTOS!$B:$B,"<"&DATE(2026,13,1)) -> 0 | O10: =SUM(E10:N10) -> 0 | P10: =SUMIFS(MOVIMIENTOS!$I:$I,MOVIMIENTOS!$D:$D,"Aporte",MOVIMIENTOS!$E:$E,"Extraordinaria",MOVIMIENTOS!$F:$F,P$4,MOVIMIENTOS!$J:$J,$C10) -> 0 | Q10: =SUMIFS(MOVIMIENTOS!$I:$I,MOVIMIENTOS!$D:$D,"Aporte",MOVIMIENTOS!$E:$E,"Extraordinaria",MOVIMIENTOS!$F:$F,Q$4,MOVIMIENTOS!$J:$J,$C10) -> 0 | R10: =SUMIFS(MOVIMIENTOS!$I:$I,MOVIMIENTOS!$D:$D,"Aporte",MOVIMIENTOS!$E:$E,"Extraordinaria",MOVIMIENTOS!$F:$F,R$4,MOVIMIENTOS!$J:$J,$C10) -> 0 | S10: =SUMIFS(MOVIMIENTOS!$I:$I,MOVIMIENTOS!$D:$D,"Aporte",MOVIMIENTOS!$E:$E,"Extraordinaria",MOVIMIENTOS!$F:$F,S$4,MOVIMIENTOS!$J:$J,$C10) -> 0 | T10: =SUMIFS(MOVIMIENTOS!$I:$I,MOVIMIENTOS!$D:$D,"Aporte",MOVIMIENTOS!$E:$E,"Extraordinaria",MOVIMIENTOS!$F:$F,T$4,MOVIMIENTOS!$J:$J,$C10) -> 0 | U10: =SUMIFS(MOVIMIENTOS!$I:$I,MOVIMIENTOS!$D:$D,"Aporte",MOVIMIENTOS!$E:$E,"Extraordinaria",MOVIMIENTOS!$F:$F,U$4,MOVIMIENTOS!$J:$J,$C10) -> 0 | V10: =SUMIFS(MOVIMIENTOS!$I:$I,MOVIMIENTOS!$D:$D,"Aporte",MOVIMIENTOS!$E:$E,"Extraordinaria",MOVIMIENTOS!$F:$F,V$4,MOVIMIENTOS!$J:$J,$C10) -> 0 | W10: =SUM(P10:V10) -> 0 | X10: =O10+W10 -> 0
A11: 7 | B11: 24387554-4 | C11: CASTILLO GRACIA JOSEFA ANTONIA | E11: =SUMIFS(MOVIMIENTOS!$I:$I,MOVIMIENTOS!$D:$D,"Aporte",MOVIMIENTOS!$E:$E,"Anual",MOVIMIENTOS!$J:$J,$C11,MOVIMIENTOS!$B:$B,">="&DATE(2026,3,1),MOVIMIENTOS!$B:$B,"<"&DATE(2026,4,1)) -> 3000 | F11: =SUMIFS(MOVIMIENTOS!$I:$I,MOVIMIENTOS!$D:$D,"Aporte",MOVIMIENTOS!$E:$E,"Anual",MOVIMIENTOS!$J:$J,$C11,MOVIMIENTOS!$B:$B,">="&DATE(2026,4,1),MOVIMIENTOS!$B:$B,"<"&DATE(2026,5,1)) -> 3000 | G11: =SUMIFS(MOVIMIENTOS!$I:$I,MOVIMIENTOS!$D:$D,"Aporte",MOVIMIENTOS!$E:$E,"Anual",MOVIMIENTOS!$J:$J,$C11,MOVIMIENTOS!$B:$B,">="&DATE(2026,5,1),MOVIMIENTOS!$B:$B,"<"&DATE(2026,6,1)) -> 3000 | H11: =SUMIFS(MOVIMIENTOS!$I:$I,MOVIMIENTOS!$D:$D,"Aporte",MOVIMIENTOS!$E:$E,"Anual",MOVIMIENTOS!$J:$J,$C11,MOVIMIENTOS!$B:$B,">="&DATE(2026,6,1),MOVIMIENTOS!$B:$B,"<"&DATE(2026,7,1)) -> 0 | I11: =SUMIFS(MOVIMIENTOS!$I:$I,MOVIMIENTOS!$D:$D,"Aporte",MOVIMIENTOS!$E:$E,"Anual",MOVIMIENTOS!$J:$J,$C11,MOVIMIENTOS!$B:$B,">="&DATE(2026,7,1),MOVIMIENTOS!$B:$B,"<"&DATE(2026,8,1)) -> 0 | J11: =SUMIFS(MOVIMIENTOS!$I:$I,MOVIMIENTOS!$D:$D,"Aporte",MOVIMIENTOS!$E:$E,"Anual",MOVIMIENTOS!$J:$J,$C11,MOVIMIENTOS!$B:$B,">="&DATE(2026,8,1),MOVIMIENTOS!$B:$B,"<"&DATE(2026,9,1)) -> 0 | K11: =SUMIFS(MOVIMIENTOS!$I:$I,MOVIMIENTOS!$D:$D,"Aporte",MOVIMIENTOS!$E:$E,"Anual",MOVIMIENTOS!$J:$J,$C11,MOVIMIENTOS!$B:$B,">="&DATE(2026,9,1),MOVIMIENTOS!$B:$B,"<"&DATE(2026,10,1)) -> 0 | L11: =SUMIFS(MOVIMIENTOS!$I:$I,MOVIMIENTOS!$D:$D,"Aporte",MOVIMIENTOS!$E:$E,"Anual",MOVIMIENTOS!$J:$J,$C11,MOVIMIENTOS!$B:$B,">="&DATE(2026,10,1),MOVIMIENTOS!$B:$B,"<"&DATE(2026,11,1)) -> 0 | M11: =SUMIFS(MOVIMIENTOS!$I:$I,MOVIMIENTOS!$D:$D,"Aporte",MOVIMIENTOS!$E:$E,"Anual",MOVIMIENTOS!$J:$J,$C11,MOVIMIENTOS!$B:$B,">="&DATE(2026,11,1),MOVIMIENTOS!$B:$B,"<"&DATE(2026,12,1)) -> 0 | N11: =SUMIFS(MOVIMIENTOS!$I:$I,MOVIMIENTOS!$D:$D,"Aporte",MOVIMIENTOS!$E:$E,"Anual",MOVIMIENTOS!$J:$J,$C11,MOVIMIENTOS!$B:$B,">="&DATE(2026,12,1),MOVIMIENTOS!$B:$B,"<"&DATE(2026,13,1)) -> 0 | O11: =SUM(E11:N11) -> 9000 | P11: =SUMIFS(MOVIMIENTOS!$I:$I,MOVIMIENTOS!$D:$D,"Aporte",MOVIMIENTOS!$E:$E,"Extraordinaria",MOVIMIENTOS!$F:$F,P$4,MOVIMIENTOS!$J:$J,$C11) -> 1000 | Q11: =SUMIFS(MOVIMIENTOS!$I:$I,MOVIMIENTOS!$D:$D,"Aporte",MOVIMIENTOS!$E:$E,"Extraordinaria",MOVIMIENTOS!$F:$F,Q$4,MOVIMIENTOS!$J:$J,$C11) -> 0 | R11: =SUMIFS(MOVIMIENTOS!$I:$I,MOVIMIENTOS!$D:$D,"Aporte",MOVIMIENTOS!$E:$E,"Extraordinaria",MOVIMIENTOS!$F:$F,R$4,MOVIMIENTOS!$J:$J,$C11) -> 2000 | S11: =SUMIFS(MOVIMIENTOS!$I:$I,MOVIMIENTOS!$D:$D,"Aporte",MOVIMIENTOS!$E:$E,"Extraordinaria",MOVIMIENTOS!$F:$F,S$4,MOVIMIENTOS!$J:$J,$C11) -> 0 | T11: =SUMIFS(MOVIMIENTOS!$I:$I,MOVIMIENTOS!$D:$D,"Aporte",MOVIMIENTOS!$E:$E,"Extraordinaria",MOVIMIENTOS!$F:$F,T$4,MOVIMIENTOS!$J:$J,$C11) -> 0 | U11: =SUMIFS(MOVIMIENTOS!$I:$I,MOVIMIENTOS!$D:$D,"Aporte",MOVIMIENTOS!$E:$E,"Extraordinaria",MOVIMIENTOS!$F:$F,U$4,MOVIMIENTOS!$J:$J,$C11) -> 0 | V11: =SUMIFS(MOVIMIENTOS!$I:$I,MOVIMIENTOS!$D:$D,"Aporte",MOVIMIENTOS!$E:$E,"Extraordinaria",MOVIMIENTOS!$F:$F,V$4,MOVIMIENTOS!$J:$J,$C11) -> 0 | W11: =SUM(P11:V11) -> 3000 | X11: =O11+W11 -> 12000
A12: 8 | B12: 25117099-1 | C12: CASTRO VALDERRAMA EIMY PASCALLE | D12: ANA VALDERRAMA | E12: =SUMIFS(MOVIMIENTOS!$I:$I,MOVIMIENTOS!$D:$D,"Aporte",MOVIMIENTOS!$E:$E,"Anual",MOVIMIENTOS!$J:$J,$C12,MOVIMIENTOS!$B:$B,">="&DATE(2026,3,1),MOVIMIENTOS!$B:$B,"<"&DATE(2026,4,1)) -> 3000 | F12: =SUMIFS(MOVIMIENTOS!$I:$I,MOVIMIENTOS!$D:$D,"Aporte",MOVIMIENTOS!$E:$E,"Anual",MOVIMIENTOS!$J:$J,$C12,MOVIMIENTOS!$B:$B,">="&DATE(2026,4,1),MOVIMIENTOS!$B:$B,"<"&DATE(2026,5,1)) -> 3000 | G12: =SUMIFS(MOVIMIENTOS!$I:$I,MOVIMIENTOS!$D:$D,"Aporte",MOVIMIENTOS!$E:$E,"Anual",MOVIMIENTOS!$J:$J,$C12,MOVIMIENTOS!$B:$B,">="&DATE(2026,5,1),MOVIMIENTOS!$B:$B,"<"&DATE(2026,6,1)) -> 3000 | H12: =SUMIFS(MOVIMIENTOS!$I:$I,MOVIMIENTOS!$D:$D,"Aporte",MOVIMIENTOS!$E:$E,"Anual",MOVIMIENTOS!$J:$J,$C12,MOVIMIENTOS!$B:$B,">="&DATE(2026,6,1),MOVIMIENTOS!$B:$B,"<"&DATE(2026,7,1)) -> 3000 | I12: =SUMIFS(MOVIMIENTOS!$I:$I,MOVIMIENTOS!$D:$D,"Aporte",MOVIMIENTOS!$E:$E,"Anual",MOVIMIENTOS!$J:$J,$C12,MOVIMIENTOS!$B:$B,">="&DATE(2026,7,1),MOVIMIENTOS!$B:$B,"<"&DATE(2026,8,1)) -> 3000 | J12: =SUMIFS(MOVIMIENTOS!$I:$I,MOVIMIENTOS!$D:$D,"Aporte",MOVIMIENTOS!$E:$E,"Anual",MOVIMIENTOS!$J:$J,$C12,MOVIMIENTOS!$B:$B,">="&DATE(2026,8,1),MOVIMIENTOS!$B:$B,"<"&DATE(2026,9,1)) -> 0 | K12: =SUMIFS(MOVIMIENTOS!$I:$I,MOVIMIENTOS!$D:$D,"Aporte",MOVIMIENTOS!$E:$E,"Anual",MOVIMIENTOS!$J:$J,$C12,MOVIMIENTOS!$B:$B,">="&DATE(2026,9,1),MOVIMIENTOS!$B:$B,"<"&DATE(2026,10,1)) -> 0 | L12: =SUMIFS(MOVIMIENTOS!$I:$I,MOVIMIENTOS!$D:$D,"Aporte",MOVIMIENTOS!$E:$E,"Anual",MOVIMIENTOS!$J:$J,$C12,MOVIMIENTOS!$B:$B,">="&DATE(2026,10,1),MOVIMIENTOS!$B:$B,"<"&DATE(2026,11,1)) -> 0 | M12: =SUMIFS(MOVIMIENTOS!$I:$I,MOVIMIENTOS!$D:$D,"Aporte",MOVIMIENTOS!$E:$E,"Anual",MOVIMIENTOS!$J:$J,$C12,MOVIMIENTOS!$B:$B,">="&DATE(2026,11,1),MOVIMIENTOS!$B:$B,"<"&DATE(2026,12,1)) -> 0 | N12: =SUMIFS(MOVIMIENTOS!$I:$I,MOVIMIENTOS!$D:$D,"Aporte",MOVIMIENTOS!$E:$E,"Anual",MOVIMIENTOS!$J:$J,$C12,MOVIMIENTOS!$B:$B,">="&DATE(2026,12,1),MOVIMIENTOS!$B:$B,"<"&DATE(2026,13,1)) -> 0 | O12: =SUM(E12:N12) -> 15000 | P12: =SUMIFS(MOVIMIENTOS!$I:$I,MOVIMIENTOS!$D:$D,"Aporte",MOVIMIENTOS!$E:$E,"Extraordinaria",MOVIMIENTOS!$F:$F,P$4,MOVIMIENTOS!$J:$J,$C12) -> 1000 | Q12: =SUMIFS(MOVIMIENTOS!$I:$I,MOVIMIENTOS!$D:$D,"Aporte",MOVIMIENTOS!$E:$E,"Extraordinaria",MOVIMIENTOS!$F:$F,Q$4,MOVIMIENTOS!$J:$J,$C12) -> 2000 | R12: =SUMIFS(MOVIMIENTOS!$I:$I,MOVIMIENTOS!$D:$D,"Aporte",MOVIMIENTOS!$E:$E,"Extraordinaria",MOVIMIENTOS!$F:$F,R$4,MOVIMIENTOS!$J:$J,$C12) -> 2000 | S12: =SUMIFS(MOVIMIENTOS!$I:$I,MOVIMIENTOS!$D:$D,"Aporte",MOVIMIENTOS!$E:$E,"Extraordinaria",MOVIMIENTOS!$F:$F,S$4,MOVIMIENTOS!$J:$J,$C12) -> 0 | T12: =SUMIFS(MOVIMIENTOS!$I:$I,MOVIMIENTOS!$D:$D,"Aporte",MOVIMIENTOS!$E:$E,"Extraordinaria",MOVIMIENTOS!$F:$F,T$4,MOVIMIENTOS!$J:$J,$C12) -> 0 | U12: =SUMIFS(MOVIMIENTOS!$I:$I,MOVIMIENTOS!$D:$D,"Aporte",MOVIMIENTOS!$E:$E,"Extraordinaria",MOVIMIENTOS!$F:$F,U$4,MOVIMIENTOS!$J:$J,$C12) -> 0 | V12: =SUMIFS(MOVIMIENTOS!$I:$I,MOVIMIENTOS!$D:$D,"Aporte",MOVIMIENTOS!$E:$E,"Extraordinaria",MOVIMIENTOS!$F:$F,V$4,MOVIMIENTOS!$J:$J,$C12) -> 0 | W12: =SUM(P12:V12) -> 5000 | X12: =O12+W12 -> 20000
A13: 9 | B13: 25091106-8 | C13: DONOSO MONSALVE ANGEL ISAAC | E13: =SUMIFS(MOVIMIENTOS!$I:$I,MOVIMIENTOS!$D:$D,"Aporte",MOVIMIENTOS!$E:$E,"Anual",MOVIMIENTOS!$J:$J,$C13,MOVIMIENTOS!$B:$B,">="&DATE(2026,3,1),MOVIMIENTOS!$B:$B,"<"&DATE(2026,4,1)) -> 3000 | F13: =SUMIFS(MOVIMIENTOS!$I:$I,MOVIMIENTOS!$D:$D,"Aporte",MOVIMIENTOS!$E:$E,"Anual",MOVIMIENTOS!$J:$J,$C13,MOVIMIENTOS!$B:$B,">="&DATE(2026,4,1),MOVIMIENTOS!$B:$B,"<"&DATE(2026,5,1)) -> 3000 | G13: =SUMIFS(MOVIMIENTOS!$I:$I,MOVIMIENTOS!$D:$D,"Aporte",MOVIMIENTOS!$E:$E,"Anual",MOVIMIENTOS!$J:$J,$C13,MOVIMIENTOS!$B:$B,">="&DATE(2026,5,1),MOVIMIENTOS!$B:$B,"<"&DATE(2026,6,1)) -> 3000 | H13: =SUMIFS(MOVIMIENTOS!$I:$I,MOVIMIENTOS!$D:$D,"Aporte",MOVIMIENTOS!$E:$E,"Anual",MOVIMIENTOS!$J:$J,$C13,MOVIMIENTOS!$B:$B,">="&DATE(2026,6,1),MOVIMIENTOS!$B:$B,"<"&DATE(2026,7,1)) -> 3000 | I13: =SUMIFS(MOVIMIENTOS!$I:$I,MOVIMIENTOS!$D:$D,"Aporte",MOVIMIENTOS!$E:$E,"Anual",MOVIMIENTOS!$J:$J,$C13,MOVIMIENTOS!$B:$B,">="&DATE(2026,7,1),MOVIMIENTOS!$B:$B,"<"&DATE(2026,8,1)) -> 0 | J13: =SUMIFS(MOVIMIENTOS!$I:$I,MOVIMIENTOS!$D:$D,"Aporte",MOVIMIENTOS!$E:$E,"Anual",MOVIMIENTOS!$J:$J,$C13,MOVIMIENTOS!$B:$B,">="&DATE(2026,8,1),MOVIMIENTOS!$B:$B,"<"&DATE(2026,9,1)) -> 0 | K13: =SUMIFS(MOVIMIENTOS!$I:$I,MOVIMIENTOS!$D:$D,"Aporte",MOVIMIENTOS!$E:$E,"Anual",MOVIMIENTOS!$J:$J,$C13,MOVIMIENTOS!$B:$B,">="&DATE(2026,9,1),MOVIMIENTOS!$B:$B,"<"&DATE(2026,10,1)) -> 0 | L13: =SUMIFS(MOVIMIENTOS!$I:$I,MOVIMIENTOS!$D:$D,"Aporte",MOVIMIENTOS!$E:$E,"Anual",MOVIMIENTOS!$J:$J,$C13,MOVIMIENTOS!$B:$B,">="&DATE(2026,10,1),MOVIMIENTOS!$B:$B,"<"&DATE(2026,11,1)) -> 0 | M13: =SUMIFS(MOVIMIENTOS!$I:$I,MOVIMIENTOS!$D:$D,"Aporte",MOVIMIENTOS!$E:$E,"Anual",MOVIMIENTOS!$J:$J,$C13,MOVIMIENTOS!$B:$B,">="&DATE(2026,11,1),MOVIMIENTOS!$B:$B,"<"&DATE(2026,12,1)) -> 0 | N13: =SUMIFS(MOVIMIENTOS!$I:$I,MOVIMIENTOS!$D:$D,"Aporte",MOVIMIENTOS!$E:$E,"Anual",MOVIMIENTOS!$J:$J,$C13,MOVIMIENTOS!$B:$B,">="&DATE(2026,12,1),MOVIMIENTOS!$B:$B,"<"&DATE(2026,13,1)) -> 0 | O13: =SUM(E13:N13) -> 12000 | P13: =SUMIFS(MOVIMIENTOS!$I:$I,MOVIMIENTOS!$D:$D,"Aporte",MOVIMIENTOS!$E:$E,"Extraordinaria",MOVIMIENTOS!$F:$F,P$4,MOVIMIENTOS!$J:$J,$C13) -> 1000 | Q13: =SUMIFS(MOVIMIENTOS!$I:$I,MOVIMIENTOS!$D:$D,"Aporte",MOVIMIENTOS!$E:$E,"Extraordinaria",MOVIMIENTOS!$F:$F,Q$4,MOVIMIENTOS!$J:$J,$C13) -> 2000 | R13: =SUMIFS(MOVIMIENTOS!$I:$I,MOVIMIENTOS!$D:$D,"Aporte",MOVIMIENTOS!$E:$E,"Extraordinaria",MOVIMIENTOS!$F:$F,R$4,MOVIMIENTOS!$J:$J,$C13) -> 2000 | S13: =SUMIFS(MOVIMIENTOS!$I:$I,MOVIMIENTOS!$D:$D,"Aporte",MOVIMIENTOS!$E:$E,"Extraordinaria",MOVIMIENTOS!$F:$F,S$4,MOVIMIENTOS!$J:$J,$C13) -> 0 | T13: =SUMIFS(MOVIMIENTOS!$I:$I,MOVIMIENTOS!$D:$D,"Aporte",MOVIMIENTOS!$E:$E,"Extraordinaria",MOVIMIENTOS!$F:$F,T$4,MOVIMIENTOS!$J:$J,$C13) -> 0 | U13: =SUMIFS(MOVIMIENTOS!$I:$I,MOVIMIENTOS!$D:$D,"Aporte",MOVIMIENTOS!$E:$E,"Extraordinaria",MOVIMIENTOS!$F:$F,U$4,MOVIMIENTOS!$J:$J,$C13) -> 0 | V13: =SUMIFS(MOVIMIENTOS!$I:$I,MOVIMIENTOS!$D:$D,"Aporte",MOVIMIENTOS!$E:$E,"Extraordinaria",MOVIMIENTOS!$F:$F,V$4,MOVIMIENTOS!$J:$J,$C13) -> 0 | W13: =SUM(P13:V13) -> 5000 | X13: =O13+W13 -> 17000
A14: 10 | B14: 25091116-5 | C14: DONOSO MONSALVE THOMAS IGNACIO | E14: =SUMIFS(MOVIMIENTOS!$I:$I,MOVIMIENTOS!$D:$D,"Aporte",MOVIMIENTOS!$E:$E,"Anual",MOVIMIENTOS!$J:$J,$C14,MOVIMIENTOS!$B:$B,">="&DATE(2026,3,1),MOVIMIENTOS!$B:$B,"<"&DATE(2026,4,1)) -> 3000 | F14: =SUMIFS(MOVIMIENTOS!$I:$I,MOVIMIENTOS!$D:$D,"Aporte",MOVIMIENTOS!$E:$E,"Anual",MOVIMIENTOS!$J:$J,$C14,MOVIMIENTOS!$B:$B,">="&DATE(2026,4,1),MOVIMIENTOS!$B:$B,"<"&DATE(2026,5,1)) -> 3000 | G14: =SUMIFS(MOVIMIENTOS!$I:$I,MOVIMIENTOS!$D:$D,"Aporte",MOVIMIENTOS!$E:$E,"Anual",MOVIMIENTOS!$J:$J,$C14,MOVIMIENTOS!$B:$B,">="&DATE(2026,5,1),MOVIMIENTOS!$B:$B,"<"&DATE(2026,6,1)) -> 3000 | H14: =SUMIFS(MOVIMIENTOS!$I:$I,MOVIMIENTOS!$D:$D,"Aporte",MOVIMIENTOS!$E:$E,"Anual",MOVIMIENTOS!$J:$J,$C14,MOVIMIENTOS!$B:$B,">="&DATE(2026,6,1),MOVIMIENTOS!$B:$B,"<"&DATE(2026,7,1)) -> 3000 | I14: =SUMIFS(MOVIMIENTOS!$I:$I,MOVIMIENTOS!$D:$D,"Aporte",MOVIMIENTOS!$E:$E,"Anual",MOVIMIENTOS!$J:$J,$C14,MOVIMIENTOS!$B:$B,">="&DATE(2026,7,1),MOVIMIENTOS!$B:$B,"<"&DATE(2026,8,1)) -> 0 | J14: =SUMIFS(MOVIMIENTOS!$I:$I,MOVIMIENTOS!$D:$D,"Aporte",MOVIMIENTOS!$E:$E,"Anual",MOVIMIENTOS!$J:$J,$C14,MOVIMIENTOS!$B:$B,">="&DATE(2026,8,1),MOVIMIENTOS!$B:$B,"<"&DATE(2026,9,1)) -> 0 | K14: =SUMIFS(MOVIMIENTOS!$I:$I,MOVIMIENTOS!$D:$D,"Aporte",MOVIMIENTOS!$E:$E,"Anual",MOVIMIENTOS!$J:$J,$C14,MOVIMIENTOS!$B:$B,">="&DATE(2026,9,1),MOVIMIENTOS!$B:$B,"<"&DATE(2026,10,1)) -> 0 | L14: =SUMIFS(MOVIMIENTOS!$I:$I,MOVIMIENTOS!$D:$D,"Aporte",MOVIMIENTOS!$E:$E,"Anual",MOVIMIENTOS!$J:$J,$C14,MOVIMIENTOS!$B:$B,">="&DATE(2026,10,1),MOVIMIENTOS!$B:$B,"<"&DATE(2026,11,1)) -> 0 | M14: =SUMIFS(MOVIMIENTOS!$I:$I,MOVIMIENTOS!$D:$D,"Aporte",MOVIMIENTOS!$E:$E,"Anual",MOVIMIENTOS!$J:$J,$C14,MOVIMIENTOS!$B:$B,">="&DATE(2026,11,1),MOVIMIENTOS!$B:$B,"<"&DATE(2026,12,1)) -> 0 | N14: =SUMIFS(MOVIMIENTOS!$I:$I,MOVIMIENTOS!$D:$D,"Aporte",MOVIMIENTOS!$E:$E,"Anual",MOVIMIENTOS!$J:$J,$C14,MOVIMIENTOS!$B:$B,">="&DATE(2026,12,1),MOVIMIENTOS!$B:$B,"<"&DATE(2026,13,1)) -> 0 | O14: =SUM(E14:N14) -> 12000 | P14: =SUMIFS(MOVIMIENTOS!$I:$I,MOVIMIENTOS!$D:$D,"Aporte",MOVIMIENTOS!$E:$E,"Extraordinaria",MOVIMIENTOS!$F:$F,P$4,MOVIMIENTOS!$J:$J,$C14) -> 1000 | Q14: =SUMIFS(MOVIMIENTOS!$I:$I,MOVIMIENTOS!$D:$D,"Aporte",MOVIMIENTOS!$E:$E,"Extraordinaria",MOVIMIENTOS!$F:$F,Q$4,MOVIMIENTOS!$J:$J,$C14) -> 2000 | R14: =SUMIFS(MOVIMIENTOS!$I:$I,MOVIMIENTOS!$D:$D,"Aporte",MOVIMIENTOS!$E:$E,"Extraordinaria",MOVIMIENTOS!$F:$F,R$4,MOVIMIENTOS!$J:$J,$C14) -> 2000 | S14: =SUMIFS(MOVIMIENTOS!$I:$I,MOVIMIENTOS!$D:$D,"Aporte",MOVIMIENTOS!$E:$E,"Extraordinaria",MOVIMIENTOS!$F:$F,S$4,MOVIMIENTOS!$J:$J,$C14) -> 0 | T14: =SUMIFS(MOVIMIENTOS!$I:$I,MOVIMIENTOS!$D:$D,"Aporte",MOVIMIENTOS!$E:$E,"Extraordinaria",MOVIMIENTOS!$F:$F,T$4,MOVIMIENTOS!$J:$J,$C14) -> 0 | U14: =SUMIFS(MOVIMIENTOS!$I:$I,MOVIMIENTOS!$D:$D,"Aporte",MOVIMIENTOS!$E:$E,"Extraordinaria",MOVIMIENTOS!$F:$F,U$4,MOVIMIENTOS!$J:$J,$C14) -> 0 | V14: =SUMIFS(MOVIMIENTOS!$I:$I,MOVIMIENTOS!$D:$D,"Aporte",MOVIMIENTOS!$E:$E,"Extraordinaria",MOVIMIENTOS!$F:$F,V$4,MOVIMIENTOS!$J:$J,$C14) -> 0 | W14: =SUM(P14:V14) -> 5000 | X14: =O14+W14 -> 17000
A15: 11 | B15: 24953133-2 | C15: DONOSO ZAMORA SOFÍA ELENA | D15: JENNY ZAMORA | E15: =SUMIFS(MOVIMIENTOS!$I:$I,MOVIMIENTOS!$D:$D,"Aporte",MOVIMIENTOS!$E:$E,"Anual",MOVIMIENTOS!$J:$J,$C15,MOVIMIENTOS!$B:$B,">="&DATE(2026,3,1),MOVIMIENTOS!$B:$B,"<"&DATE(2026,4,1)) -> 3000 | F15: =SUMIFS(MOVIMIENTOS!$I:$I,MOVIMIENTOS!$D:$D,"Aporte",MOVIMIENTOS!$E:$E,"Anual",MOVIMIENTOS!$J:$J,$C15,MOVIMIENTOS!$B:$B,">="&DATE(2026,4,1),MOVIMIENTOS!$B:$B,"<"&DATE(2026,5,1)) -> 3000 | G15: =SUMIFS(MOVIMIENTOS!$I:$I,MOVIMIENTOS!$D:$D,"Aporte",MOVIMIENTOS!$E:$E,"Anual",MOVIMIENTOS!$J:$J,$C15,MOVIMIENTOS!$B:$B,">="&DATE(2026,5,1),MOVIMIENTOS!$B:$B,"<"&DATE(2026,6,1)) -> 3000 | H15: =SUMIFS(MOVIMIENTOS!$I:$I,MOVIMIENTOS!$D:$D,"Aporte",MOVIMIENTOS!$E:$E,"Anual",MOVIMIENTOS!$J:$J,$C15,MOVIMIENTOS!$B:$B,">="&DATE(2026,6,1),MOVIMIENTOS!$B:$B,"<"&DATE(2026,7,1)) -> 3000 | I15: =SUMIFS(MOVIMIENTOS!$I:$I,MOVIMIENTOS!$D:$D,"Aporte",MOVIMIENTOS!$E:$E,"Anual",MOVIMIENTOS!$J:$J,$C15,MOVIMIENTOS!$B:$B,">="&DATE(2026,7,1),MOVIMIENTOS!$B:$B,"<"&DATE(2026,8,1)) -> 3000 | J15: =SUMIFS(MOVIMIENTOS!$I:$I,MOVIMIENTOS!$D:$D,"Aporte",MOVIMIENTOS!$E:$E,"Anual",MOVIMIENTOS!$J:$J,$C15,MOVIMIENTOS!$B:$B,">="&DATE(2026,8,1),MOVIMIENTOS!$B:$B,"<"&DATE(2026,9,1)) -> 0 | K15: =SUMIFS(MOVIMIENTOS!$I:$I,MOVIMIENTOS!$D:$D,"Aporte",MOVIMIENTOS!$E:$E,"Anual",MOVIMIENTOS!$J:$J,$C15,MOVIMIENTOS!$B:$B,">="&DATE(2026,9,1),MOVIMIENTOS!$B:$B,"<"&DATE(2026,10,1)) -> 0 | L15: =SUMIFS(MOVIMIENTOS!$I:$I,MOVIMIENTOS!$D:$D,"Aporte",MOVIMIENTOS!$E:$E,"Anual",MOVIMIENTOS!$J:$J,$C15,MOVIMIENTOS!$B:$B,">="&DATE(2026,10,1),MOVIMIENTOS!$B:$B,"<"&DATE(2026,11,1)) -> 0 | M15: =SUMIFS(MOVIMIENTOS!$I:$I,MOVIMIENTOS!$D:$D,"Aporte",MOVIMIENTOS!$E:$E,"Anual",MOVIMIENTOS!$J:$J,$C15,MOVIMIENTOS!$B:$B,">="&DATE(2026,11,1),MOVIMIENTOS!$B:$B,"<"&DATE(2026,12,1)) -> 0 | N15: =SUMIFS(MOVIMIENTOS!$I:$I,MOVIMIENTOS!$D:$D,"Aporte",MOVIMIENTOS!$E:$E,"Anual",MOVIMIENTOS!$J:$J,$C15,MOVIMIENTOS!$B:$B,">="&DATE(2026,12,1),MOVIMIENTOS!$B:$B,"<"&DATE(2026,13,1)) -> 0 | O15: =SUM(E15:N15) -> 15000 | P15: =SUMIFS(MOVIMIENTOS!$I:$I,MOVIMIENTOS!$D:$D,"Aporte",MOVIMIENTOS!$E:$E,"Extraordinaria",MOVIMIENTOS!$F:$F,P$4,MOVIMIENTOS!$J:$J,$C15) -> 1000 | Q15: =SUMIFS(MOVIMIENTOS!$I:$I,MOVIMIENTOS!$D:$D,"Aporte",MOVIMIENTOS!$E:$E,"Extraordinaria",MOVIMIENTOS!$F:$F,Q$4,MOVIMIENTOS!$J:$J,$C15) -> 2000 | R15: =SUMIFS(MOVIMIENTOS!$I:$I,MOVIMIENTOS!$D:$D,"Aporte",MOVIMIENTOS!$E:$E,"Extraordinaria",MOVIMIENTOS!$F:$F,R$4,MOVIMIENTOS!$J:$J,$C15) -> 2000 | S15: =SUMIFS(MOVIMIENTOS!$I:$I,MOVIMIENTOS!$D:$D,"Aporte",MOVIMIENTOS!$E:$E,"Extraordinaria",MOVIMIENTOS!$F:$F,S$4,MOVIMIENTOS!$J:$J,$C15) -> 0 | T15: =SUMIFS(MOVIMIENTOS!$I:$I,MOVIMIENTOS!$D:$D,"Aporte",MOVIMIENTOS!$E:$E,"Extraordinaria",MOVIMIENTOS!$F:$F,T$4,MOVIMIENTOS!$J:$J,$C15) -> 0 | U15: =SUMIFS(MOVIMIENTOS!$I:$I,MOVIMIENTOS!$D:$D,"Aporte",MOVIMIENTOS!$E:$E,"Extraordinaria",MOVIMIENTOS!$F:$F,U$4,MOVIMIENTOS!$J:$J,$C15) -> 1000 | V15: =SUMIFS(MOVIMIENTOS!$I:$I,MOVIMIENTOS!$D:$D,"Aporte",MOVIMIENTOS!$E:$E,"Extraordinaria",MOVIMIENTOS!$F:$F,V$4,MOVIMIENTOS!$J:$J,$C15) -> 0 | W15: =SUM(P15:V15) -> 6000 | X15: =O15+W15 -> 21000
A16: 12 | B16: 24751135-0 | C16: INOSTROZA MOLINA MATÍAS ALONSO | D16: OLGA MOLINA | E16: =SUMIFS(MOVIMIENTOS!$I:$I,MOVIMIENTOS!$D:$D,"Aporte",MOVIMIENTOS!$E:$E,"Anual",MOVIMIENTOS!$J:$J,$C16,MOVIMIENTOS!$B:$B,">="&DATE(2026,3,1),MOVIMIENTOS!$B:$B,"<"&DATE(2026,4,1)) -> 3000 | F16: =SUMIFS(MOVIMIENTOS!$I:$I,MOVIMIENTOS!$D:$D,"Aporte",MOVIMIENTOS!$E:$E,"Anual",MOVIMIENTOS!$J:$J,$C16,MOVIMIENTOS!$B:$B,">="&DATE(2026,4,1),MOVIMIENTOS!$B:$B,"<"&DATE(2026,5,1)) -> 3000 | G16: =SUMIFS(MOVIMIENTOS!$I:$I,MOVIMIENTOS!$D:$D,"Aporte",MOVIMIENTOS!$E:$E,"Anual",MOVIMIENTOS!$J:$J,$C16,MOVIMIENTOS!$B:$B,">="&DATE(2026,5,1),MOVIMIENTOS!$B:$B,"<"&DATE(2026,6,1)) -> 3000 | H16: =SUMIFS(MOVIMIENTOS!$I:$I,MOVIMIENTOS!$D:$D,"Aporte",MOVIMIENTOS!$E:$E,"Anual",MOVIMIENTOS!$J:$J,$C16,MOVIMIENTOS!$B:$B,">="&DATE(2026,6,1),MOVIMIENTOS!$B:$B,"<"&DATE(2026,7,1)) -> 3000 | I16: =SUMIFS(MOVIMIENTOS!$I:$I,MOVIMIENTOS!$D:$D,"Aporte",MOVIMIENTOS!$E:$E,"Anual",MOVIMIENTOS!$J:$J,$C16,MOVIMIENTOS!$B:$B,">="&DATE(2026,7,1),MOVIMIENTOS!$B:$B,"<"&DATE(2026,8,1)) -> 3000 | J16: =SUMIFS(MOVIMIENTOS!$I:$I,MOVIMIENTOS!$D:$D,"Aporte",MOVIMIENTOS!$E:$E,"Anual",MOVIMIENTOS!$J:$J,$C16,MOVIMIENTOS!$B:$B,">="&DATE(2026,8,1),MOVIMIENTOS!$B:$B,"<"&DATE(2026,9,1)) -> 3000 | K16: =SUMIFS(MOVIMIENTOS!$I:$I,MOVIMIENTOS!$D:$D,"Aporte",MOVIMIENTOS!$E:$E,"Anual",MOVIMIENTOS!$J:$J,$C16,MOVIMIENTOS!$B:$B,">="&DATE(2026,9,1),MOVIMIENTOS!$B:$B,"<"&DATE(2026,10,1)) -> 0 | L16: =SUMIFS(MOVIMIENTOS!$I:$I,MOVIMIENTOS!$D:$D,"Aporte",MOVIMIENTOS!$E:$E,"Anual",MOVIMIENTOS!$J:$J,$C16,MOVIMIENTOS!$B:$B,">="&DATE(2026,10,1),MOVIMIENTOS!$B:$B,"<"&DATE(2026,11,1)) -> 0 | M16: =SUMIFS(MOVIMIENTOS!$I:$I,MOVIMIENTOS!$D:$D,"Aporte",MOVIMIENTOS!$E:$E,"Anual",MOVIMIENTOS!$J:$J,$C16,MOVIMIENTOS!$B:$B,">="&DATE(2026,11,1),MOVIMIENTOS!$B:$B,"<"&DATE(2026,12,1)) -> 0 | N16: =SUMIFS(MOVIMIENTOS!$I:$I,MOVIMIENTOS!$D:$D,"Aporte",MOVIMIENTOS!$E:$E,"Anual",MOVIMIENTOS!$J:$J,$C16,MOVIMIENTOS!$B:$B,">="&DATE(2026,12,1),MOVIMIENTOS!$B:$B,"<"&DATE(2026,13,1)) -> 0 | O16: =SUM(E16:N16) -> 18000 | P16: =SUMIFS(MOVIMIENTOS!$I:$I,MOVIMIENTOS!$D:$D,"Aporte",MOVIMIENTOS!$E:$E,"Extraordinaria",MOVIMIENTOS!$F:$F,P$4,MOVIMIENTOS!$J:$J,$C16) -> 1000 | Q16: =SUMIFS(MOVIMIENTOS!$I:$I,MOVIMIENTOS!$D:$D,"Aporte",MOVIMIENTOS!$E:$E,"Extraordinaria",MOVIMIENTOS!$F:$F,Q$4,MOVIMIENTOS!$J:$J,$C16) -> 2000 | R16: =SUMIFS(MOVIMIENTOS!$I:$I,MOVIMIENTOS!$D:$D,"Aporte",MOVIMIENTOS!$E:$E,"Extraordinaria",MOVIMIENTOS!$F:$F,R$4,MOVIMIENTOS!$J:$J,$C16) -> 0 | S16: =SUMIFS(MOVIMIENTOS!$I:$I,MOVIMIENTOS!$D:$D,"Aporte",MOVIMIENTOS!$E:$E,"Extraordinaria",MOVIMIENTOS!$F:$F,S$4,MOVIMIENTOS!$J:$J,$C16) -> 0 | T16: =SUMIFS(MOVIMIENTOS!$I:$I,MOVIMIENTOS!$D:$D,"Aporte",MOVIMIENTOS!$E:$E,"Extraordinaria",MOVIMIENTOS!$F:$F,T$4,MOVIMIENTOS!$J:$J,$C16) -> 0 | U16: =SUMIFS(MOVIMIENTOS!$I:$I,MOVIMIENTOS!$D:$D,"Aporte",MOVIMIENTOS!$E:$E,"Extraordinaria",MOVIMIENTOS!$F:$F,U$4,MOVIMIENTOS!$J:$J,$C16) -> 0 | V16: =SUMIFS(MOVIMIENTOS!$I:$I,MOVIMIENTOS!$D:$D,"Aporte",MOVIMIENTOS!$E:$E,"Extraordinaria",MOVIMIENTOS!$F:$F,V$4,MOVIMIENTOS!$J:$J,$C16) -> 0 | W16: =SUM(P16:V16) -> 3000 | X16: =O16+W16 -> 21000
A17: 13 | B17: 25049508-0 | C17: ITURRIETA HERNÁNDEZ MAXIMILIANO ALEJANDRO | D17: VALERIA HERNANDEZ | E17: =SUMIFS(MOVIMIENTOS!$I:$I,MOVIMIENTOS!$D:$D,"Aporte",MOVIMIENTOS!$E:$E,"Anual",MOVIMIENTOS!$J:$J,$C17,MOVIMIENTOS!$B:$B,">="&DATE(2026,3,1),MOVIMIENTOS!$B:$B,"<"&DATE(2026,4,1)) -> 3000 | F17: =SUMIFS(MOVIMIENTOS!$I:$I,MOVIMIENTOS!$D:$D,"Aporte",MOVIMIENTOS!$E:$E,"Anual",MOVIMIENTOS!$J:$J,$C17,MOVIMIENTOS!$B:$B,">="&DATE(2026,4,1),MOVIMIENTOS!$B:$B,"<"&DATE(2026,5,1)) -> 0 | G17: =SUMIFS(MOVIMIENTOS!$I:$I,MOVIMIENTOS!$D:$D,"Aporte",MOVIMIENTOS!$E:$E,"Anual",MOVIMIENTOS!$J:$J,$C17,MOVIMIENTOS!$B:$B,">="&DATE(2026,5,1),MOVIMIENTOS!$B:$B,"<"&DATE(2026,6,1)) -> 0 | H17: =SUMIFS(MOVIMIENTOS!$I:$I,MOVIMIENTOS!$D:$D,"Aporte",MOVIMIENTOS!$E:$E,"Anual",MOVIMIENTOS!$J:$J,$C17,MOVIMIENTOS!$B:$B,">="&DATE(2026,6,1),MOVIMIENTOS!$B:$B,"<"&DATE(2026,7,1)) -> 0 | I17: =SUMIFS(MOVIMIENTOS!$I:$I,MOVIMIENTOS!$D:$D,"Aporte",MOVIMIENTOS!$E:$E,"Anual",MOVIMIENTOS!$J:$J,$C17,MOVIMIENTOS!$B:$B,">="&DATE(2026,7,1),MOVIMIENTOS!$B:$B,"<"&DATE(2026,8,1)) -> 0 | J17: =SUMIFS(MOVIMIENTOS!$I:$I,MOVIMIENTOS!$D:$D,"Aporte",MOVIMIENTOS!$E:$E,"Anual",MOVIMIENTOS!$J:$J,$C17,MOVIMIENTOS!$B:$B,">="&DATE(2026,8,1),MOVIMIENTOS!$B:$B,"<"&DATE(2026,9,1)) -> 0 | K17: =SUMIFS(MOVIMIENTOS!$I:$I,MOVIMIENTOS!$D:$D,"Aporte",MOVIMIENTOS!$E:$E,"Anual",MOVIMIENTOS!$J:$J,$C17,MOVIMIENTOS!$B:$B,">="&DATE(2026,9,1),MOVIMIENTOS!$B:$B,"<"&DATE(2026,10,1)) -> 0 | L17: =SUMIFS(MOVIMIENTOS!$I:$I,MOVIMIENTOS!$D:$D,"Aporte",MOVIMIENTOS!$E:$E,"Anual",MOVIMIENTOS!$J:$J,$C17,MOVIMIENTOS!$B:$B,">="&DATE(2026,10,1),MOVIMIENTOS!$B:$B,"<"&DATE(2026,11,1)) -> 0 | M17: =SUMIFS(MOVIMIENTOS!$I:$I,MOVIMIENTOS!$D:$D,"Aporte",MOVIMIENTOS!$E:$E,"Anual",MOVIMIENTOS!$J:$J,$C17,MOVIMIENTOS!$B:$B,">="&DATE(2026,11,1),MOVIMIENTOS!$B:$B,"<"&DATE(2026,12,1)) -> 0 | N17: =SUMIFS(MOVIMIENTOS!$I:$I,MOVIMIENTOS!$D:$D,"Aporte",MOVIMIENTOS!$E:$E,"Anual",MOVIMIENTOS!$J:$J,$C17,MOVIMIENTOS!$B:$B,">="&DATE(2026,12,1),MOVIMIENTOS!$B:$B,"<"&DATE(2026,13,1)) -> 0 | O17: =SUM(E17:N17) -> 3000 | P17: =SUMIFS(MOVIMIENTOS!$I:$I,MOVIMIENTOS!$D:$D,"Aporte",MOVIMIENTOS!$E:$E,"Extraordinaria",MOVIMIENTOS!$F:$F,P$4,MOVIMIENTOS!$J:$J,$C17) -> 1000 | Q17: =SUMIFS(MOVIMIENTOS!$I:$I,MOVIMIENTOS!$D:$D,"Aporte",MOVIMIENTOS!$E:$E,"Extraordinaria",MOVIMIENTOS!$F:$F,Q$4,MOVIMIENTOS!$J:$J,$C17) -> 2000 | R17: =SUMIFS(MOVIMIENTOS!$I:$I,MOVIMIENTOS!$D:$D,"Aporte",MOVIMIENTOS!$E:$E,"Extraordinaria",MOVIMIENTOS!$F:$F,R$4,MOVIMIENTOS!$J:$J,$C17) -> 2000 | S17: =SUMIFS(MOVIMIENTOS!$I:$I,MOVIMIENTOS!$D:$D,"Aporte",MOVIMIENTOS!$E:$E,"Extraordinaria",MOVIMIENTOS!$F:$F,S$4,MOVIMIENTOS!$J:$J,$C17) -> 0 | T17: =SUMIFS(MOVIMIENTOS!$I:$I,MOVIMIENTOS!$D:$D,"Aporte",MOVIMIENTOS!$E:$E,"Extraordinaria",MOVIMIENTOS!$F:$F,T$4,MOVIMIENTOS!$J:$J,$C17) -> 0 | U17: =SUMIFS(MOVIMIENTOS!$I:$I,MOVIMIENTOS!$D:$D,"Aporte",MOVIMIENTOS!$E:$E,"Extraordinaria",MOVIMIENTOS!$F:$F,U$4,MOVIMIENTOS!$J:$J,$C17) -> 0 | V17: =SUMIFS(MOVIMIENTOS!$I:$I,MOVIMIENTOS!$D:$D,"Aporte",MOVIMIENTOS!$E:$E,"Extraordinaria",MOVIMIENTOS!$F:$F,V$4,MOVIMIENTOS!$J:$J,$C17) -> 0 | W17: =SUM(P17:V17) -> 5000 | X17: =O17+W17 -> 8000
A18: 14 | B18: 25049482-3 | C18: ITURRIETA HERNÁNDEZ VICENTE IGNACIO | D18: VALERIA HERNANDEZ | E18: =SUMIFS(MOVIMIENTOS!$I:$I,MOVIMIENTOS!$D:$D,"Aporte",MOVIMIENTOS!$E:$E,"Anual",MOVIMIENTOS!$J:$J,$C18,MOVIMIENTOS!$B:$B,">="&DATE(2026,3,1),MOVIMIENTOS!$B:$B,"<"&DATE(2026,4,1)) -> 3000 | F18: =SUMIFS(MOVIMIENTOS!$I:$I,MOVIMIENTOS!$D:$D,"Aporte",MOVIMIENTOS!$E:$E,"Anual",MOVIMIENTOS!$J:$J,$C18,MOVIMIENTOS!$B:$B,">="&DATE(2026,4,1),MOVIMIENTOS!$B:$B,"<"&DATE(2026,5,1)) -> 0 | G18: =SUMIFS(MOVIMIENTOS!$I:$I,MOVIMIENTOS!$D:$D,"Aporte",MOVIMIENTOS!$E:$E,"Anual",MOVIMIENTOS!$J:$J,$C18,MOVIMIENTOS!$B:$B,">="&DATE(2026,5,1),MOVIMIENTOS!$B:$B,"<"&DATE(2026,6,1)) -> 0 | H18: =SUMIFS(MOVIMIENTOS!$I:$I,MOVIMIENTOS!$D:$D,"Aporte",MOVIMIENTOS!$E:$E,"Anual",MOVIMIENTOS!$J:$J,$C18,MOVIMIENTOS!$B:$B,">="&DATE(2026,6,1),MOVIMIENTOS!$B:$B,"<"&DATE(2026,7,1)) -> 0 | I18: =SUMIFS(MOVIMIENTOS!$I:$I,MOVIMIENTOS!$D:$D,"Aporte",MOVIMIENTOS!$E:$E,"Anual",MOVIMIENTOS!$J:$J,$C18,MOVIMIENTOS!$B:$B,">="&DATE(2026,7,1),MOVIMIENTOS!$B:$B,"<"&DATE(2026,8,1)) -> 0 | J18: =SUMIFS(MOVIMIENTOS!$I:$I,MOVIMIENTOS!$D:$D,"Aporte",MOVIMIENTOS!$E:$E,"Anual",MOVIMIENTOS!$J:$J,$C18,MOVIMIENTOS!$B:$B,">="&DATE(2026,8,1),MOVIMIENTOS!$B:$B,"<"&DATE(2026,9,1)) -> 0 | K18: =SUMIFS(MOVIMIENTOS!$I:$I,MOVIMIENTOS!$D:$D,"Aporte",MOVIMIENTOS!$E:$E,"Anual",MOVIMIENTOS!$J:$J,$C18,MOVIMIENTOS!$B:$B,">="&DATE(2026,9,1),MOVIMIENTOS!$B:$B,"<"&DATE(2026,10,1)) -> 0 | L18: =SUMIFS(MOVIMIENTOS!$I:$I,MOVIMIENTOS!$D:$D,"Aporte",MOVIMIENTOS!$E:$E,"Anual",MOVIMIENTOS!$J:$J,$C18,MOVIMIENTOS!$B:$B,">="&DATE(2026,10,1),MOVIMIENTOS!$B:$B,"<"&DATE(2026,11,1)) -> 0 | M18: =SUMIFS(MOVIMIENTOS!$I:$I,MOVIMIENTOS!$D:$D,"Aporte",MOVIMIENTOS!$E:$E,"Anual",MOVIMIENTOS!$J:$J,$C18,MOVIMIENTOS!$B:$B,">="&DATE(2026,11,1),MOVIMIENTOS!$B:$B,"<"&DATE(2026,12,1)) -> 0 | N18: =SUMIFS(MOVIMIENTOS!$I:$I,MOVIMIENTOS!$D:$D,"Aporte",MOVIMIENTOS!$E:$E,"Anual",MOVIMIENTOS!$J:$J,$C18,MOVIMIENTOS!$B:$B,">="&DATE(2026,12,1),MOVIMIENTOS!$B:$B,"<"&DATE(2026,13,1)) -> 0 | O18: =SUM(E18:N18) -> 3000 | P18: =SUMIFS(MOVIMIENTOS!$I:$I,MOVIMIENTOS!$D:$D,"Aporte",MOVIMIENTOS!$E:$E,"Extraordinaria",MOVIMIENTOS!$F:$F,P$4,MOVIMIENTOS!$J:$J,$C18) -> 1000 | Q18: =SUMIFS(MOVIMIENTOS!$I:$I,MOVIMIENTOS!$D:$D,"Aporte",MOVIMIENTOS!$E:$E,"Extraordinaria",MOVIMIENTOS!$F:$F,Q$4,MOVIMIENTOS!$J:$J,$C18) -> 2000 | R18: =SUMIFS(MOVIMIENTOS!$I:$I,MOVIMIENTOS!$D:$D,"Aporte",MOVIMIENTOS!$E:$E,"Extraordinaria",MOVIMIENTOS!$F:$F,R$4,MOVIMIENTOS!$J:$J,$C18) -> 2000 | S18: =SUMIFS(MOVIMIENTOS!$I:$I,MOVIMIENTOS!$D:$D,"Aporte",MOVIMIENTOS!$E:$E,"Extraordinaria",MOVIMIENTOS!$F:$F,S$4,MOVIMIENTOS!$J:$J,$C18) -> 0 | T18: =SUMIFS(MOVIMIENTOS!$I:$I,MOVIMIENTOS!$D:$D,"Aporte",MOVIMIENTOS!$E:$E,"Extraordinaria",MOVIMIENTOS!$F:$F,T$4,MOVIMIENTOS!$J:$J,$C18) -> 0 | U18: =SUMIFS(MOVIMIENTOS!$I:$I,MOVIMIENTOS!$D:$D,"Aporte",MOVIMIENTOS!$E:$E,"Extraordinaria",MOVIMIENTOS!$F:$F,U$4,MOVIMIENTOS!$J:$J,$C18) -> 0 | V18: =SUMIFS(MOVIMIENTOS!$I:$I,MOVIMIENTOS!$D:$D,"Aporte",MOVIMIENTOS!$E:$E,"Extraordinaria",MOVIMIENTOS!$F:$F,V$4,MOVIMIENTOS!$J:$J,$C18) -> 0 | W18: =SUM(P18:V18) -> 5000 | X18: =O18+W18 -> 8000
A19: 15 | B19: 25067494-5 | C19: JATIB DÍAZ ABDOLASIS MAXIMILIANO | D19: MARISOL DIAZ | E19: =SUMIFS(MOVIMIENTOS!$I:$I,MOVIMIENTOS!$D:$D,"Aporte",MOVIMIENTOS!$E:$E,"Anual",MOVIMIENTOS!$J:$J,$C19,MOVIMIENTOS!$B:$B,">="&DATE(2026,3,1),MOVIMIENTOS!$B:$B,"<"&DATE(2026,4,1)) -> 3000 | F19: =SUMIFS(MOVIMIENTOS!$I:$I,MOVIMIENTOS!$D:$D,"Aporte",MOVIMIENTOS!$E:$E,"Anual",MOVIMIENTOS!$J:$J,$C19,MOVIMIENTOS!$B:$B,">="&DATE(2026,4,1),MOVIMIENTOS!$B:$B,"<"&DATE(2026,5,1)) -> 0 | G19: =SUMIFS(MOVIMIENTOS!$I:$I,MOVIMIENTOS!$D:$D,"Aporte",MOVIMIENTOS!$E:$E,"Anual",MOVIMIENTOS!$J:$J,$C19,MOVIMIENTOS!$B:$B,">="&DATE(2026,5,1),MOVIMIENTOS!$B:$B,"<"&DATE(2026,6,1)) -> 0 | H19: =SUMIFS(MOVIMIENTOS!$I:$I,MOVIMIENTOS!$D:$D,"Aporte",MOVIMIENTOS!$E:$E,"Anual",MOVIMIENTOS!$J:$J,$C19,MOVIMIENTOS!$B:$B,">="&DATE(2026,6,1),MOVIMIENTOS!$B:$B,"<"&DATE(2026,7,1)) -> 0 | I19: =SUMIFS(MOVIMIENTOS!$I:$I,MOVIMIENTOS!$D:$D,"Aporte",MOVIMIENTOS!$E:$E,"Anual",MOVIMIENTOS!$J:$J,$C19,MOVIMIENTOS!$B:$B,">="&DATE(2026,7,1),MOVIMIENTOS!$B:$B,"<"&DATE(2026,8,1)) -> 0 | J19: =SUMIFS(MOVIMIENTOS!$I:$I,MOVIMIENTOS!$D:$D,"Aporte",MOVIMIENTOS!$E:$E,"Anual",MOVIMIENTOS!$J:$J,$C19,MOVIMIENTOS!$B:$B,">="&DATE(2026,8,1),MOVIMIENTOS!$B:$B,"<"&DATE(2026,9,1)) -> 0 | K19: =SUMIFS(MOVIMIENTOS!$I:$I,MOVIMIENTOS!$D:$D,"Aporte",MOVIMIENTOS!$E:$E,"Anual",MOVIMIENTOS!$J:$J,$C19,MOVIMIENTOS!$B:$B,">="&DATE(2026,9,1),MOVIMIENTOS!$B:$B,"<"&DATE(2026,10,1)) -> 0 | L19: =SUMIFS(MOVIMIENTOS!$I:$I,MOVIMIENTOS!$D:$D,"Aporte",MOVIMIENTOS!$E:$E,"Anual",MOVIMIENTOS!$J:$J,$C19,MOVIMIENTOS!$B:$B,">="&DATE(2026,10,1),MOVIMIENTOS!$B:$B,"<"&DATE(2026,11,1)) -> 0 | M19: =SUMIFS(MOVIMIENTOS!$I:$I,MOVIMIENTOS!$D:$D,"Aporte",MOVIMIENTOS!$E:$E,"Anual",MOVIMIENTOS!$J:$J,$C19,MOVIMIENTOS!$B:$B,">="&DATE(2026,11,1),MOVIMIENTOS!$B:$B,"<"&DATE(2026,12,1)) -> 0 | N19: =SUMIFS(MOVIMIENTOS!$I:$I,MOVIMIENTOS!$D:$D,"Aporte",MOVIMIENTOS!$E:$E,"Anual",MOVIMIENTOS!$J:$J,$C19,MOVIMIENTOS!$B:$B,">="&DATE(2026,12,1),MOVIMIENTOS!$B:$B,"<"&DATE(2026,13,1)) -> 0 | O19: =SUM(E19:N19) -> 3000 | P19: =SUMIFS(MOVIMIENTOS!$I:$I,MOVIMIENTOS!$D:$D,"Aporte",MOVIMIENTOS!$E:$E,"Extraordinaria",MOVIMIENTOS!$F:$F,P$4,MOVIMIENTOS!$J:$J,$C19) -> 1000 | Q19: =SUMIFS(MOVIMIENTOS!$I:$I,MOVIMIENTOS!$D:$D,"Aporte",MOVIMIENTOS!$E:$E,"Extraordinaria",MOVIMIENTOS!$F:$F,Q$4,MOVIMIENTOS!$J:$J,$C19) -> 2000 | R19: =SUMIFS(MOVIMIENTOS!$I:$I,MOVIMIENTOS!$D:$D,"Aporte",MOVIMIENTOS!$E:$E,"Extraordinaria",MOVIMIENTOS!$F:$F,R$4,MOVIMIENTOS!$J:$J,$C19) -> 2000 | S19: =SUMIFS(MOVIMIENTOS!$I:$I,MOVIMIENTOS!$D:$D,"Aporte",MOVIMIENTOS!$E:$E,"Extraordinaria",MOVIMIENTOS!$F:$F,S$4,MOVIMIENTOS!$J:$J,$C19) -> 0 | T19: =SUMIFS(MOVIMIENTOS!$I:$I,MOVIMIENTOS!$D:$D,"Aporte",MOVIMIENTOS!$E:$E,"Extraordinaria",MOVIMIENTOS!$F:$F,T$4,MOVIMIENTOS!$J:$J,$C19) -> 0 | U19: =SUMIFS(MOVIMIENTOS!$I:$I,MOVIMIENTOS!$D:$D,"Aporte",MOVIMIENTOS!$E:$E,"Extraordinaria",MOVIMIENTOS!$F:$F,U$4,MOVIMIENTOS!$J:$J,$C19) -> 0 | V19: =SUMIFS(MOVIMIENTOS!$I:$I,MOVIMIENTOS!$D:$D,"Aporte",MOVIMIENTOS!$E:$E,"Extraordinaria",MOVIMIENTOS!$F:$F,V$4,MOVIMIENTOS!$J:$J,$C19) -> 0 | W19: =SUM(P19:V19) -> 5000 | X19: =O19+W19 -> 8000
A20: 16 | B20: 25015009-1 | C20: MENESES YÁÑEZ ALEXANDRA MODESTA | E20: =SUMIFS(MOVIMIENTOS!$I:$I,MOVIMIENTOS!$D:$D,"Aporte",MOVIMIENTOS!$E:$E,"Anual",MOVIMIENTOS!$J:$J,$C20,MOVIMIENTOS!$B:$B,">="&DATE(2026,3,1),MOVIMIENTOS!$B:$B,"<"&DATE(2026,4,1)) -> 0 | F20: =SUMIFS(MOVIMIENTOS!$I:$I,MOVIMIENTOS!$D:$D,"Aporte",MOVIMIENTOS!$E:$E,"Anual",MOVIMIENTOS!$J:$J,$C20,MOVIMIENTOS!$B:$B,">="&DATE(2026,4,1),MOVIMIENTOS!$B:$B,"<"&DATE(2026,5,1)) -> 0 | G20: =SUMIFS(MOVIMIENTOS!$I:$I,MOVIMIENTOS!$D:$D,"Aporte",MOVIMIENTOS!$E:$E,"Anual",MOVIMIENTOS!$J:$J,$C20,MOVIMIENTOS!$B:$B,">="&DATE(2026,5,1),MOVIMIENTOS!$B:$B,"<"&DATE(2026,6,1)) -> 0 | H20: =SUMIFS(MOVIMIENTOS!$I:$I,MOVIMIENTOS!$D:$D,"Aporte",MOVIMIENTOS!$E:$E,"Anual",MOVIMIENTOS!$J:$J,$C20,MOVIMIENTOS!$B:$B,">="&DATE(2026,6,1),MOVIMIENTOS!$B:$B,"<"&DATE(2026,7,1)) -> 0 | I20: =SUMIFS(MOVIMIENTOS!$I:$I,MOVIMIENTOS!$D:$D,"Aporte",MOVIMIENTOS!$E:$E,"Anual",MOVIMIENTOS!$J:$J,$C20,MOVIMIENTOS!$B:$B,">="&DATE(2026,7,1),MOVIMIENTOS!$B:$B,"<"&DATE(2026,8,1)) -> 0 | J20: =SUMIFS(MOVIMIENTOS!$I:$I,MOVIMIENTOS!$D:$D,"Aporte",MOVIMIENTOS!$E:$E,"Anual",MOVIMIENTOS!$J:$J,$C20,MOVIMIENTOS!$B:$B,">="&DATE(2026,8,1),MOVIMIENTOS!$B:$B,"<"&DATE(2026,9,1)) -> 0 | K20: =SUMIFS(MOVIMIENTOS!$I:$I,MOVIMIENTOS!$D:$D,"Aporte",MOVIMIENTOS!$E:$E,"Anual",MOVIMIENTOS!$J:$J,$C20,MOVIMIENTOS!$B:$B,">="&DATE(2026,9,1),MOVIMIENTOS!$B:$B,"<"&DATE(2026,10,1)) -> 0 | L20: =SUMIFS(MOVIMIENTOS!$I:$I,MOVIMIENTOS!$D:$D,"Aporte",MOVIMIENTOS!$E:$E,"Anual",MOVIMIENTOS!$J:$J,$C20,MOVIMIENTOS!$B:$B,">="&DATE(2026,10,1),MOVIMIENTOS!$B:$B,"<"&DATE(2026,11,1)) -> 0 | M20: =SUMIFS(MOVIMIENTOS!$I:$I,MOVIMIENTOS!$D:$D,"Aporte",MOVIMIENTOS!$E:$E,"Anual",MOVIMIENTOS!$J:$J,$C20,MOVIMIENTOS!$B:$B,">="&DATE(2026,11,1),MOVIMIENTOS!$B:$B,"<"&DATE(2026,12,1)) -> 0 | N20: =SUMIFS(MOVIMIENTOS!$I:$I,MOVIMIENTOS!$D:$D,"Aporte",MOVIMIENTOS!$E:$E,"Anual",MOVIMIENTOS!$J:$J,$C20,MOVIMIENTOS!$B:$B,">="&DATE(2026,12,1),MOVIMIENTOS!$B:$B,"<"&DATE(2026,13,1)) -> 0 | O20: =SUM(E20:N20) -> 0 | P20: =SUMIFS(MOVIMIENTOS!$I:$I,MOVIMIENTOS!$D:$D,"Aporte",MOVIMIENTOS!$E:$E,"Extraordinaria",MOVIMIENTOS!$F:$F,P$4,MOVIMIENTOS!$J:$J,$C20) -> 1000 | Q20: =SUMIFS(MOVIMIENTOS!$I:$I,MOVIMIENTOS!$D:$D,"Aporte",MOVIMIENTOS!$E:$E,"Extraordinaria",MOVIMIENTOS!$F:$F,Q$4,MOVIMIENTOS!$J:$J,$C20) -> 2000 | R20: =SUMIFS(MOVIMIENTOS!$I:$I,MOVIMIENTOS!$D:$D,"Aporte",MOVIMIENTOS!$E:$E,"Extraordinaria",MOVIMIENTOS!$F:$F,R$4,MOVIMIENTOS!$J:$J,$C20) -> 2000 | S20: =SUMIFS(MOVIMIENTOS!$I:$I,MOVIMIENTOS!$D:$D,"Aporte",MOVIMIENTOS!$E:$E,"Extraordinaria",MOVIMIENTOS!$F:$F,S$4,MOVIMIENTOS!$J:$J,$C20) -> 0 | T20: =SUMIFS(MOVIMIENTOS!$I:$I,MOVIMIENTOS!$D:$D,"Aporte",MOVIMIENTOS!$E:$E,"Extraordinaria",MOVIMIENTOS!$F:$F,T$4,MOVIMIENTOS!$J:$J,$C20) -> 0 | U20: =SUMIFS(MOVIMIENTOS!$I:$I,MOVIMIENTOS!$D:$D,"Aporte",MOVIMIENTOS!$E:$E,"Extraordinaria",MOVIMIENTOS!$F:$F,U$4,MOVIMIENTOS!$J:$J,$C20) -> 0 | V20: =SUMIFS(MOVIMIENTOS!$I:$I,MOVIMIENTOS!$D:$D,"Aporte",MOVIMIENTOS!$E:$E,"Extraordinaria",MOVIMIENTOS!$F:$F,V$4,MOVIMIENTOS!$J:$J,$C20) -> 0 | W20: =SUM(P20:V20) -> 5000 | X20: =O20+W20 -> 5000
A21: 17 | B21: 25179616-5 | C21: MICHEA ALIAGA JOAQUÍN ELÍAS | D21: STEFANY ALIAGA | E21: =SUMIFS(MOVIMIENTOS!$I:$I,MOVIMIENTOS!$D:$D,"Aporte",MOVIMIENTOS!$E:$E,"Anual",MOVIMIENTOS!$J:$J,$C21,MOVIMIENTOS!$B:$B,">="&DATE(2026,3,1),MOVIMIENTOS!$B:$B,"<"&DATE(2026,4,1)) -> 3000 | F21: =SUMIFS(MOVIMIENTOS!$I:$I,MOVIMIENTOS!$D:$D,"Aporte",MOVIMIENTOS!$E:$E,"Anual",MOVIMIENTOS!$J:$J,$C21,MOVIMIENTOS!$B:$B,">="&DATE(2026,4,1),MOVIMIENTOS!$B:$B,"<"&DATE(2026,5,1)) -> 3000 | G21: =SUMIFS(MOVIMIENTOS!$I:$I,MOVIMIENTOS!$D:$D,"Aporte",MOVIMIENTOS!$E:$E,"Anual",MOVIMIENTOS!$J:$J,$C21,MOVIMIENTOS!$B:$B,">="&DATE(2026,5,1),MOVIMIENTOS!$B:$B,"<"&DATE(2026,6,1)) -> 3000 | H21: =SUMIFS(MOVIMIENTOS!$I:$I,MOVIMIENTOS!$D:$D,"Aporte",MOVIMIENTOS!$E:$E,"Anual",MOVIMIENTOS!$J:$J,$C21,MOVIMIENTOS!$B:$B,">="&DATE(2026,6,1),MOVIMIENTOS!$B:$B,"<"&DATE(2026,7,1)) -> 3000 | I21: =SUMIFS(MOVIMIENTOS!$I:$I,MOVIMIENTOS!$D:$D,"Aporte",MOVIMIENTOS!$E:$E,"Anual",MOVIMIENTOS!$J:$J,$C21,MOVIMIENTOS!$B:$B,">="&DATE(2026,7,1),MOVIMIENTOS!$B:$B,"<"&DATE(2026,8,1)) -> 3000 | J21: =SUMIFS(MOVIMIENTOS!$I:$I,MOVIMIENTOS!$D:$D,"Aporte",MOVIMIENTOS!$E:$E,"Anual",MOVIMIENTOS!$J:$J,$C21,MOVIMIENTOS!$B:$B,">="&DATE(2026,8,1),MOVIMIENTOS!$B:$B,"<"&DATE(2026,9,1)) -> 0 | K21: =SUMIFS(MOVIMIENTOS!$I:$I,MOVIMIENTOS!$D:$D,"Aporte",MOVIMIENTOS!$E:$E,"Anual",MOVIMIENTOS!$J:$J,$C21,MOVIMIENTOS!$B:$B,">="&DATE(2026,9,1),MOVIMIENTOS!$B:$B,"<"&DATE(2026,10,1)) -> 0 | L21: =SUMIFS(MOVIMIENTOS!$I:$I,MOVIMIENTOS!$D:$D,"Aporte",MOVIMIENTOS!$E:$E,"Anual",MOVIMIENTOS!$J:$J,$C21,MOVIMIENTOS!$B:$B,">="&DATE(2026,10,1),MOVIMIENTOS!$B:$B,"<"&DATE(2026,11,1)) -> 0 | M21: =SUMIFS(MOVIMIENTOS!$I:$I,MOVIMIENTOS!$D:$D,"Aporte",MOVIMIENTOS!$E:$E,"Anual",MOVIMIENTOS!$J:$J,$C21,MOVIMIENTOS!$B:$B,">="&DATE(2026,11,1),MOVIMIENTOS!$B:$B,"<"&DATE(2026,12,1)) -> 0 | N21: =SUMIFS(MOVIMIENTOS!$I:$I,MOVIMIENTOS!$D:$D,"Aporte",MOVIMIENTOS!$E:$E,"Anual",MOVIMIENTOS!$J:$J,$C21,MOVIMIENTOS!$B:$B,">="&DATE(2026,12,1),MOVIMIENTOS!$B:$B,"<"&DATE(2026,13,1)) -> 0 | O21: =SUM(E21:N21) -> 15000 | P21: =SUMIFS(MOVIMIENTOS!$I:$I,MOVIMIENTOS!$D:$D,"Aporte",MOVIMIENTOS!$E:$E,"Extraordinaria",MOVIMIENTOS!$F:$F,P$4,MOVIMIENTOS!$J:$J,$C21) -> 1000 | Q21: =SUMIFS(MOVIMIENTOS!$I:$I,MOVIMIENTOS!$D:$D,"Aporte",MOVIMIENTOS!$E:$E,"Extraordinaria",MOVIMIENTOS!$F:$F,Q$4,MOVIMIENTOS!$J:$J,$C21) -> 2000 | R21: =SUMIFS(MOVIMIENTOS!$I:$I,MOVIMIENTOS!$D:$D,"Aporte",MOVIMIENTOS!$E:$E,"Extraordinaria",MOVIMIENTOS!$F:$F,R$4,MOVIMIENTOS!$J:$J,$C21) -> 2000 | S21: =SUMIFS(MOVIMIENTOS!$I:$I,MOVIMIENTOS!$D:$D,"Aporte",MOVIMIENTOS!$E:$E,"Extraordinaria",MOVIMIENTOS!$F:$F,S$4,MOVIMIENTOS!$J:$J,$C21) -> 0 | T21: =SUMIFS(MOVIMIENTOS!$I:$I,MOVIMIENTOS!$D:$D,"Aporte",MOVIMIENTOS!$E:$E,"Extraordinaria",MOVIMIENTOS!$F:$F,T$4,MOVIMIENTOS!$J:$J,$C21) -> 0 | U21: =SUMIFS(MOVIMIENTOS!$I:$I,MOVIMIENTOS!$D:$D,"Aporte",MOVIMIENTOS!$E:$E,"Extraordinaria",MOVIMIENTOS!$F:$F,U$4,MOVIMIENTOS!$J:$J,$C21) -> 0 | V21: =SUMIFS(MOVIMIENTOS!$I:$I,MOVIMIENTOS!$D:$D,"Aporte",MOVIMIENTOS!$E:$E,"Extraordinaria",MOVIMIENTOS!$F:$F,V$4,MOVIMIENTOS!$J:$J,$C21) -> 0 | W21: =SUM(P21:V21) -> 5000 | X21: =O21+W21 -> 20000
A22: 18 | B22: 25026561-1 | C22: MOYA SALAS COLOMBA AYLÉN | D22: NATALIE SALAS | E22: =SUMIFS(MOVIMIENTOS!$I:$I,MOVIMIENTOS!$D:$D,"Aporte",MOVIMIENTOS!$E:$E,"Anual",MOVIMIENTOS!$J:$J,$C22,MOVIMIENTOS!$B:$B,">="&DATE(2026,3,1),MOVIMIENTOS!$B:$B,"<"&DATE(2026,4,1)) -> 3000 | F22: =SUMIFS(MOVIMIENTOS!$I:$I,MOVIMIENTOS!$D:$D,"Aporte",MOVIMIENTOS!$E:$E,"Anual",MOVIMIENTOS!$J:$J,$C22,MOVIMIENTOS!$B:$B,">="&DATE(2026,4,1),MOVIMIENTOS!$B:$B,"<"&DATE(2026,5,1)) -> 0 | G22: =SUMIFS(MOVIMIENTOS!$I:$I,MOVIMIENTOS!$D:$D,"Aporte",MOVIMIENTOS!$E:$E,"Anual",MOVIMIENTOS!$J:$J,$C22,MOVIMIENTOS!$B:$B,">="&DATE(2026,5,1),MOVIMIENTOS!$B:$B,"<"&DATE(2026,6,1)) -> 0 | H22: =SUMIFS(MOVIMIENTOS!$I:$I,MOVIMIENTOS!$D:$D,"Aporte",MOVIMIENTOS!$E:$E,"Anual",MOVIMIENTOS!$J:$J,$C22,MOVIMIENTOS!$B:$B,">="&DATE(2026,6,1),MOVIMIENTOS!$B:$B,"<"&DATE(2026,7,1)) -> 0 | I22: =SUMIFS(MOVIMIENTOS!$I:$I,MOVIMIENTOS!$D:$D,"Aporte",MOVIMIENTOS!$E:$E,"Anual",MOVIMIENTOS!$J:$J,$C22,MOVIMIENTOS!$B:$B,">="&DATE(2026,7,1),MOVIMIENTOS!$B:$B,"<"&DATE(2026,8,1)) -> 0 | J22: =SUMIFS(MOVIMIENTOS!$I:$I,MOVIMIENTOS!$D:$D,"Aporte",MOVIMIENTOS!$E:$E,"Anual",MOVIMIENTOS!$J:$J,$C22,MOVIMIENTOS!$B:$B,">="&DATE(2026,8,1),MOVIMIENTOS!$B:$B,"<"&DATE(2026,9,1)) -> 0 | K22: =SUMIFS(MOVIMIENTOS!$I:$I,MOVIMIENTOS!$D:$D,"Aporte",MOVIMIENTOS!$E:$E,"Anual",MOVIMIENTOS!$J:$J,$C22,MOVIMIENTOS!$B:$B,">="&DATE(2026,9,1),MOVIMIENTOS!$B:$B,"<"&DATE(2026,10,1)) -> 0 | L22: =SUMIFS(MOVIMIENTOS!$I:$I,MOVIMIENTOS!$D:$D,"Aporte",MOVIMIENTOS!$E:$E,"Anual",MOVIMIENTOS!$J:$J,$C22,MOVIMIENTOS!$B:$B,">="&DATE(2026,10,1),MOVIMIENTOS!$B:$B,"<"&DATE(2026,11,1)) -> 0 | M22: =SUMIFS(MOVIMIENTOS!$I:$I,MOVIMIENTOS!$D:$D,"Aporte",MOVIMIENTOS!$E:$E,"Anual",MOVIMIENTOS!$J:$J,$C22,MOVIMIENTOS!$B:$B,">="&DATE(2026,11,1),MOVIMIENTOS!$B:$B,"<"&DATE(2026,12,1)) -> 0 | N22: =SUMIFS(MOVIMIENTOS!$I:$I,MOVIMIENTOS!$D:$D,"Aporte",MOVIMIENTOS!$E:$E,"Anual",MOVIMIENTOS!$J:$J,$C22,MOVIMIENTOS!$B:$B,">="&DATE(2026,12,1),MOVIMIENTOS!$B:$B,"<"&DATE(2026,13,1)) -> 0 | O22: =SUM(E22:N22) -> 3000 | P22: =SUMIFS(MOVIMIENTOS!$I:$I,MOVIMIENTOS!$D:$D,"Aporte",MOVIMIENTOS!$E:$E,"Extraordinaria",MOVIMIENTOS!$F:$F,P$4,MOVIMIENTOS!$J:$J,$C22) -> 1000 | Q22: =SUMIFS(MOVIMIENTOS!$I:$I,MOVIMIENTOS!$D:$D,"Aporte",MOVIMIENTOS!$E:$E,"Extraordinaria",MOVIMIENTOS!$F:$F,Q$4,MOVIMIENTOS!$J:$J,$C22) -> 2000 | R22: =SUMIFS(MOVIMIENTOS!$I:$I,MOVIMIENTOS!$D:$D,"Aporte",MOVIMIENTOS!$E:$E,"Extraordinaria",MOVIMIENTOS!$F:$F,R$4,MOVIMIENTOS!$J:$J,$C22) -> 2000 | S22: =SUMIFS(MOVIMIENTOS!$I:$I,MOVIMIENTOS!$D:$D,"Aporte",MOVIMIENTOS!$E:$E,"Extraordinaria",MOVIMIENTOS!$F:$F,S$4,MOVIMIENTOS!$J:$J,$C22) -> 0 | T22: =SUMIFS(MOVIMIENTOS!$I:$I,MOVIMIENTOS!$D:$D,"Aporte",MOVIMIENTOS!$E:$E,"Extraordinaria",MOVIMIENTOS!$F:$F,T$4,MOVIMIENTOS!$J:$J,$C22) -> 0 | U22: =SUMIFS(MOVIMIENTOS!$I:$I,MOVIMIENTOS!$D:$D,"Aporte",MOVIMIENTOS!$E:$E,"Extraordinaria",MOVIMIENTOS!$F:$F,U$4,MOVIMIENTOS!$J:$J,$C22) -> 1000 | V22: =SUMIFS(MOVIMIENTOS!$I:$I,MOVIMIENTOS!$D:$D,"Aporte",MOVIMIENTOS!$E:$E,"Extraordinaria",MOVIMIENTOS!$F:$F,V$4,MOVIMIENTOS!$J:$J,$C22) -> 0 | W22: =SUM(P22:V22) -> 6000 | X22: =O22+W22 -> 9000
